Workbook

Sheet Misc Data + Calculations
A1: Date | B1: EWBC | C1: KRE | D1: Low | E1: Close | F1: Adj Close | G1: Volume
A2: 44739 | B2: 67.010002 | C2: 59.939999 | D2: 66.139999 | E2: 66.889999 | F2: 65.116997 | G2: 545000
A3: 44740 | B3: 67.330002 | C3: 59.919998 | D3: 66.419998 | E3: 67.019997 | F3: 65.243546 | G3: 1125900
A4: 44741 | B4: 67.220001 | C4: 59.18 | D4: 65.980003 | E4: 66.43 | F4: 64.669189 | G4: 966400
A5: 44742 | B5: 64.449997 | C5: 57.599998 | D5: 63.200001 | E5: 64.800003 | F5: 63.082401 | G5: 1171600
A6: 44743 | B6: 64.809998 | C6: 57.860001 | D6: 64.150002 | E6: 65.699997 | F6: 63.958534 | G6: 620800
A7: 44747 | B7: 63.880001 | C7: 58 | D7: 63.25 | E7: 66.419998 | F7: 64.659447 | G7: 680500
A8: 44748 | B8: 65.720001 | C8: 59.029999 | D8: 64.690002 | E8: 66.089996 | F8: 64.338203 | G8: 707000 | Y8: Loans | AB8: Deposits | AF8: 17.0% 17.4% 17.9% 18.5% 19.2%
A9: 44749 | B9: 66.470001 | C9: 59.27 | D9: 66.470001 | E9: 67.260002 | F9: 65.47718 | G9: 534000 | X9: CRE | Y9: 0.4 | AA9: Demand | AB9: 0.3
A10: 44750 | B10: 67.650002 | C10: 59.580002 | D10: 66.370003 | E10: 67.279999 | F10: 65.496658 | G10: 648100 | X10: C&I | Y10: 0.31 | AA10: Time | AB10: 0.3
A11: 44753 | B11: 66.370003 | C11: 58.73 | D11: 65.290001 | E11: 65.639999 | F11: 63.900131 | G11: 693600 | X11: Resi | Y11: 0.29 | AA11: Money Mkt | AB11: 0.21 | AF11: Q4 19 | AG11: 0.127
A12: 44754 | B12: 65.010002 | C12: 58.189999 | D12: 65 | E12: 66.050003 | F12: 64.299263 | G12: 567000 | AA12: Checking | AB12: 0.19 | AF12: Q1 20 | AG12: 0.127
A13: 44755 | B13: 65.540001 | C13: 58.16 | D13: 64.550003 | E13: 65.160004 | F13: 63.432854 | G13: 577200 | AF13: Q2 20 | AG13: 0.131
A14: 44756 | B14: 63.630001 | C14: 56.720001 | D14: 62.790001 | E14: 63.860001 | F14: 62.167309 | G14: 588600 | AF14: Q3 20 | AG14: 0.139
A15: 44757 | B15: 65.129997 | C15: 57.810001 | D15: 64.010002 | E15: 66.400002 | F15: 64.639984 | G15: 554000 | AF15: Q4 20 | AG15: 0.147
A16: 44760 | B16: 67.199997 | C16: 59.41 | D16: 67.080002 | E16: 67.379997 | F16: 65.594002 | G16: 956400 | AF16: Q1 21 | AG16: 0.155
A17: 44761 | B17: 68.550003 | C17: 59.75 | D17: 68.279999 | E17: 69.790001 | F17: 67.940125 | G17: 837100 | AF17: Q2 21 | AG17: 0.165
A18: 44762 | B18: 68.970001 | C18: 60.619999 | D18: 68.550003 | E18: 71.160004 | F18: 69.273811 | G18: 1150400 | AF18: Q3 21 | AG18: 0.168
A19: 44763 | B19: 71.169998 | C19: 61.48 | D19: 69.959999 | E19: 71.589996 | F19: 69.692406 | G19: 1214400 | AF19: Q4 21 | AG19: 0.17
A20: 44764 | B20: 71.93 | C20: 61.950001 | D20: 69.32 | E20: 69.849998 | F20: 67.998535 | G20: 652700 | AF20: Q1 22 | AG20: 0.172
A21: 44767 | B21: 70.879997 | C21: 61.560001 | D21: 70.510002 | E21: 72.089996 | F21: 70.179161 | G21: 727800 | AF21: Q2 22 | AG21: 0.17
A22: 44768 | B22: 71.160004 | C22: 61.849998 | D22: 69.370003 | E22: 69.389999 | F22: 67.550728 | G22: 606000 | AF22: Q3 22 | AG22: 0.174
A23: 44769 | B23: 69.650002 | C23: 61.900002 | D23: 69.489998 | E23: 70.790001 | F23: 68.913628 | G23: 618600 | AF23: Q4 22 | AG23: 0.179
A24: 44770 | B24: 70.470001 | C24: 62.810001 | D24: 68.959999 | E24: 70.459999 | F24: 68.592369 | G24: 603700 | AF24: Q1 23 | AG24: 0.185
A25: 44771 | B25: 70.099998 | C25: 62.919998 | D25: 70 | E25: 71.779999 | F25: 70.276337 | G25: 1010300 | AF25: Q2 23 | AG25: 0.192
A26: 44774 | B26: 71.059998 | C26: 63.389999 | D26: 70.410004 | E26: 71.440002 | F26: 69.943459 | G26: 906600
A27: 44775 | B27: 71.040001 | C27: 63.619999 | D27: 69.959999 | E27: 70.190002 | F27: 68.71965 | G27: 732400
A28: 44776 | B28: 70.849998 | C28: 63.540001 | D28: 70.260002 | E28: 70.699997 | F28: 69.218964 | G28: 658900 | AF28: New York | AG28: 0.22975
A29: 44777 | B29: 70.440002 | C29: 63.759998 | D29: 69.029999 | E29: 69.120003 | F29: 67.672066 | G29: 589600 | AF29: LA | AG29: 0.258
A30: 44778 | B30: 68.68 | C30: 63.25 | D30: 68.589996 | E30: 70.230003 | F30: 68.758812 | G30: 480200 | AF30: Chicago | AG30: 0.238
A31: 44781 | B31: 70.389999 | C31: 64.199997 | D31: 69.980003 | E31: 70.150002 | F31: 68.680481 | G31: 373100 | AF31: Houston | AG31: 0.252
A32: 44782 | B32: 70.260002 | C32: 64.029999 | D32: 69.25 | E32: 70.089996 | F32: 68.621735 | G32: 536700 | AF32: Phoenix | AG32: 0.261
A33: 44783 | B33: 71.529999 | C33: 64.989998 | D33: 71.209999 | E33: 73.900002 | F33: 72.351929 | G33: 827700 | AF33: Philly | AG33: 0.203
A34: 44784 | B34: 74.230003 | C34: 66.139999 | D34: 74.230003 | E34: 74.660004 | F34: 73.096008 | G34: 506000
A35: 44785 | B35: 75.199997 | C35: 67.040001 | D35: 74.75 | E35: 75.989998 | F35: 74.398148 | G35: 447300
A36: 44788 | B36: 75.419998 | C36: 66.93 | D36: 75.120003 | E36: 76.540001 | F36: 74.936623 | G36: 509200
A37: 44789 | B37: 76.080002 | C37: 67.559998 | D37: 76.080002 | E37: 77.57 | F37: 75.945053 | G37: 483100
A38: 44790 | B38: 76.389999 | C38: 67.720001 | D38: 75.980003 | E38: 76.470001 | F38: 74.868088 | G38: 509200
A39: 44791 | B39: 76.830002 | C39: 67.800003 | D39: 76.209999 | E39: 77.209999 | F39: 75.59259 | G39: 411700
A40: 44792 | B40: 76.720001 | C40: 67.550003 | D40: 75.839996 | E40: 76.339996 | F40: 74.740814 | G40: 802000
...

Sheet Net Income Build
A3: x | B3: East West Bancorp Net Income Build ($m) | C3: 2009 | D3: 2010 | E3: 2011 | F3: 2012 | G3: 2013 | H3: 2014 | I3: 2015 | J3: 2016 | K3: 2017 | L3: 2018 | M3: 2019 | N3: 2020 | O3: 2021 | P3: 2022 | Q3: 2023 | R3: 2024 | S3: 2025 | T3: 2026 | U3: 2027 | V3: 2028 | W3: 2029 | X3: 2030 | Y3: 2031 | Z3: 2032
B4: Average FFR | C4: 0.0016 | D4: 0.0018 | E4: 0.001 | F4: 0.0014 | G4: 0.0011 | H4: 0.0009 | I4: 0.0013 | J4: 0.004 | K4: 0.01 | L4: 0.0183 | M4: 0.0216 | N4: 0.0038 | O4: 0.0008 | P4: 0.0168 | Q4: 0.0508 | R4: 0.0488 | S4: 0.0418 | T4: 0.0338 | U4: 0.025
B5: Cash and Cash with Banks | C5: =CW44 -> 881282 | D5: =CT44 -> 828039 | E5: =CO44 -> 1018490 | F5: =CL44 -> 1457153 | G5: =CI44 -> 1184709 | H5: =CD43 -> 1469200 | I5: =CA43 -> 1851604 | J5: =BX43 -> 1893064 | K5: =BS43 -> 2242256 | L5: =BP43 -> 2609463 | M5: =BM43 -> 3050954 | N5: =BE41 -> 4236430 | O5: =BB41 -> 6071896 | P5: =AY41 -> 3127234 | Q5: =Q$17*Q9/Q$21 -> 4449546.8 | R5: =R$17*R9/R$21 -> 3877362.9 | S5: =S$17*S9/S$21 -> 3758059.4 | T5: =T$17*T9/T$21 -> 3945962.4 | U5: =U$17*U9/U$21 -> 4044611.4
B6: Growth | D6: =D5/C5-1 -> -0.060415395 | E6: =E5/D5-1 -> 0.23000245 | F6: =F5/E5-1 -> 0.43069937 | G6: =G5/F5-1 -> -0.18697007 | H6: =H5/G5-1 -> 0.24013576 | I6: =I5/H5-1 -> 0.26028042 | J6: =J5/I5-1 -> 0.022391397 | K6: =K5/J5-1 -> 0.18445863 | ... U6: =U5/T5-1 -> 0.025
B7: Yield | C7: =CY44 -> 0.0103 | D7: =CV44 -> 0.0116 | E7: =CQ44 -> 0.0222 | F7: =CN44 -> 0.0153 | G7: =CK44 -> 0.0146 | H7: =CF43 -> 0.0158 | I7: =CC43 -> 0.0097 | J7: =BZ43 -> 0.0078 | K7: =BU43 -> 0.0149 | L7: =BR43 -> 0.021 | M7: =BO43 -> 0.0219 | N7: =BH41 -> 0.0059 | O7: =BD41 -> 0.0026 | P7: =BA41 -> 0.0131 | Q7: ='Misc Data + Calculations'!AY573 -> 0.0466 | R7: ='Misc Data + Calculations'!AZ573 -> 0.05 | S7: ='Misc Data + Calculations'!BA573 -> 0.044015748 | T7: ='Misc Data + Calculations'!BB573 -> 0.036457306 | U7: ='Misc Data + Calculations'!BC573 -> 0.029322838
B8: Delta to FFR | C8: =C7-C$4 -> 0.0087 | D8: =D7-D$4 -> 0.0098 | E8: =E7-E$4 -> 0.0212 | F8: =F7-F$4 -> 0.0139 | G8: =G7-G$4 -> 0.0135 | H8: =H7-H$4 -> 0.0149 | I8: =I7-I$4 -> 0.0084 | J8: =J7-J$4 -> 0.0038 | ... U8: =U7-U$4 -> 0.004322838
B9: % of IEA | C9: =C5/(SUM(C$5,C$11,C$17,C$23)) -> 0.068259223 | D9: =D5/(SUM(D$5,D$11,D$17,D$23)) -> 0.046714527 | E9: =E5/(SUM(E$5,E$11,E$17,E$23)) -> 0.05251734 | F9: =F5/(SUM(F$5,F$11,F$17,F$23)) -> 0.073440844 | G9: =G5/(SUM(G$5,G$11,G$17,G$23)) -> 0.054275592 | H9: =H5/(SUM(H$5,H$11,H$17,H$23)) -> 0.056948875 | I9: =I5/(SUM(I$5,I$11,I$17,I$23)) -> 0.065218952 | J9: =J5/(SUM(J$5,J$11,J$17,J$23)) -> 0.06048751 | ... P9: =P5/(SUM(P$5,P$11,P$17,P$23)) -> 0.05272776 | Q9: 0.07 | R9: 0.065 | S9: 0.06 | T9: 0.06 | U9: 0.06
B10: Cash Interest Earned (+) | C10: =C5*C7 -> 9077.2046 | D10: =D5*D7 -> 9605.2524 | E10: =E5*E7 -> 22610.478 | F10: =F5*F7 -> 22294.441 | G10: =G5*G7 -> 17296.751 | H10: =H5*H7 -> 23213.36 | I10: =I5*I7 -> 17960.559 | J10: =J5*J7 -> 14765.899 | ... U10: =U5*U7 -> 118599.49
B11: Repos | C11: =CW46 -> 89883 | D11: =CT46 -> 529817 | E11: =CO46 -> 1023043 | F11: =CL46 -> 1267284 | G11: =CI46 -> 1503014 | H11: =CD45 -> 1340411 | I11: =CA45 -> 1337274 | J11: =BX45 -> 1708470 | K11: =BS45 -> 1438767 | L11: =BP45 -> 1020822 | M11: =BM45 -> 969384 | N11: =BE44 -> 1101434 | O11: =BB44 -> 2107157 | P11: =AY44 -> 1398080 | Q11: =Q$17*Q15/Q$21 -> 635649.54 | R11: =R$17*R15/R$21 -> 596517.37 | S11: =S$17*S15/S$21 -> 2505372.9 | T11: =T$17*T15/T$21 -> 2630641.6 | U11: =U$17*U15/U$21 -> 2696407.6
B12: Growth | D12: =D11/C11-1 -> 4.8945184 | E12: =E11/D11-1 -> 0.93093653 | F12: =F11/E11-1 -> 0.23873972 | G12: =G11/F11-1 -> 0.18601198 | H12: =H11/G11-1 -> -0.10818462 | I12: =I11/H11-1 -> -0.002340327 | J12: =J11/I11-1 -> 0.27757662 | K12: =K11/J11-1 -> -0.1578623 | ... U12: =U11/T11-1 -> 0.025
B13: Yield | C13: =CY46 -> 0.0876 | D13: =CV46 -> 0.0264 | E13: =CQ46 -> 0.0188 | F13: =CN46 -> 0.0161 | G13: =CK46 -> 0.0141 | H13: =CF45 -> 0.0152 | I13: =CC45 -> 0.0148 | J13: =BZ45 -> 0.0179 | K13: =BU45 -> 0.0223 | L13: =BR45 -> 0.0287 | M13: =BO45 -> 0.0287 | N13: =BH44 -> 0.0194 | O13: =BD44 -> 0.0153 | P13: =BA44 -> 0.0213 | Q13: ='Misc Data + Calculations'!AY575 -> 0.0248 | R13: ='Misc Data + Calculations'!AZ575 -> 0.0275 | S13: ='Misc Data + Calculations'!BA575 -> 0.025305774 | T13: ='Misc Data + Calculations'!BB575 -> 0.022408747 | U13: ='Misc Data + Calculations'!BC575 -> 0.019485245
B14: Delta to FFR | C14: =C13-C$4 -> 0.086 | D14: =D13-D$4 -> 0.0246 | E14: =E13-E$4 -> 0.0178 | F14: =F13-F$4 -> 0.0147 | G14: =G13-G$4 -> 0.013 | H14: =H13-H$4 -> 0.0143 | I14: =I13-I$4 -> 0.0135 | J14: =J13-J$4 -> 0.0139 | ... U14: =U13-U$4 -> -0.0055147545
B15: % of IEA | C15: =C11/(SUM(C$5,C$11,C$17,C$23)) -> 0.0069618394 | D15: =D11/(SUM(D$5,D$11,D$17,D$23)) -> 0.029890078 | E15: =E11/(SUM(E$5,E$11,E$17,E$23)) -> 0.052752111 | F15: =F11/(SUM(F$5,F$11,F$17,F$23)) -> 0.063871403 | G15: =G11/(SUM(G$5,G$11,G$17,G$23)) -> 0.068858238 | H15: =H11/(SUM(H$5,H$11,H$17,H$23)) -> 0.051956778 | I15: =I11/(SUM(I$5,I$11,I$17,I$23)) -> 0.047102733 | J15: =J11/(SUM(J$5,J$11,J$17,J$23)) -> 0.054589331 | ... P15: =P11/(SUM(P$5,P$11,P$17,P$23)) -> 0.023572789 | Q15: 0.01 | R15: 0.01 | S15: 0.04 | T15: 0.04 | U15: 0.04 | AB15: 0.079 | AC15: 0.5 | AD15: =AC15+1 -> 1.5 | AE15: =AD15+1 -> 2.5 | AF15: =AE15+1 -> 3.5 | AG15: =AF15+1 -> 4.5
B16: Repo Interest Earned (+) | C16: =C11*C13 -> 7873.7508 | D16: =D11*D13 -> 13987.169 | E16: =E11*E13 -> 19233.208 | F16: =F11*F13 -> 20403.272 | G16: =G11*G13 -> 21192.497 | H16: =H11*H13 -> 20374.247 | I16: =I11*I13 -> 19791.655 | J16: =J11*J13 -> 30581.613 | ... U16: =U11*U13 -> 52540.164 | AB16: =SUM(P11,P17,P23) -> 56181828 | AC16: =SUM(Q11,Q17,Q23) -> 59115407 | AD16: =SUM(R11,R17,R23) -> 55774374 | AE16: =SUM(S11,S17,S23) -> 58876264 | AF16: =SUM(T11,T17,T23) -> 61820077 | AG16: =SUM(U11,U17,U23) -> 63365579
B17: Loans | C17: =CW56 -> 9232854 | D17: =CT56 -> 13708914 | E17: =CO56 -> 14037426 | F17: =CL56 -> 14469438 | G17: =CI56 -> 16275997 | H17: =CD52 -> 20351818 | I17: =CA52 -> 22276589 | J17: =BX52 -> 24264895 | K17: =BS52 -> 27252756 | L17: =BP52 -> 30230014 | M17: =BM52 -> 33373136 | N17: =BE52 -> 36799017 | O17: =BB52 -> 39716697 | P17: =AY52 -> 45319458 | Q17: =P17*(1+Q18) -> 48945015 | R17: =Q17*(1+R18) -> 47721389 | S17: =R17*(1+S18) -> 50107459 | T17: =S17*(1+T18) -> 52612832 | U17: =T17*(1+U18) -> 53928152 | AB17: =SUM(P31,P42,P48) -> 55107002 | AC17: =SUM(Q31,Q42,Q48) -> 59088426 | AD17: =SUM(R31,R42,R48) -> 56020761 | AE17: =SUM(S31,S42,S48) -> 57506367 | AF17: =SUM(T31,T42,T48) -> 59395540 | AG17: =SUM(U31,U42,U48) -> 60842018
B18: Growth | D18: =D17/C17-1 -> 0.48479701 | E18: =E17/D17-1 -> 0.023963386 | F18: =F17/E17-1 -> 0.030775728 | G18: =G17/F17-1 -> 0.12485343 | H18: =H17/G17-1 -> 0.25041913 | I18: =I17/H17-1 -> 0.094574893 | J18: =J17/I17-1 -> 0.089255406 | K18: =K17/J17-1 -> 0.12313513 | ... P18: =P17/O17-1 -> 0.14106815 | Q18: 0.08 | R18: -0.025 | S18: 0.05 | T18: 0.05 | U18: 0.025 | AB18: =AB16-AB17 -> 1074826 | AC18: =AC16-AC17 -> 26981.379 | AD18: =AD16-AD17 -> -246387.61 | AE18: =AE16-AE17 -> 1369896.9 | AF18: =AF16-AF17 -> 2424537.2 | AG18: =AG16-AG17 -> 2523561
B19: Yield | C19: =CY56 -> 0.063594962 | D19: =CV56 -> 0.072842313 | E19: =CQ56 -> 0.067376882 | F19: =CN56 -> 0.065346698 | G19: =CK56 -> 0.060174132 | H19: =CF52 -> 0.052 | I19: =CC52 -> 0.0435 | J19: =BZ52 -> 0.0427 | K19: =BU52 -> 0.044 | L19: =BR52 -> 0.0497 | M19: =BO52 -> 0.0515 | N19: =BH52 -> 0.0398 | O19: =BD52 -> 0.0359 | P19: =BA52 -> 0.0452 | Q19: ='Misc Data + Calculations'!AY577 -> 0.0633 | R19: ='Misc Data + Calculations'!AZ577 -> 0.065 | S19: ='Misc Data + Calculations'!BA577 -> 0.062735236 | T19: ='Misc Data + Calculations'!BB577 -> 0.058917129 | U19: ='Misc Data + Calculations'!BC577 -> 0.054625199 | AC19: =AC18-AB18 -> -1047844.6 | AD19: =AD18-AC18 -> -273368.99 | AE19: =AE18-AD18 -> 1616284.5 | AF19: =AF18-AE18 -> 1054640.3 | AG19: =AG18-AF18 -> 99023.795
B20: Delta to FFR | C20: =C19-C$4 -> 0.061994962 | D20: =D19-D$4 -> 0.071042313 | E20: =E19-E$4 -> 0.066376882 | F20: =F19-F$4 -> 0.063946698 | G20: =G19-G$4 -> 0.059074132 | H20: =H19-H$4 -> 0.0511 | I20: =I19-I$4 -> 0.0422 | J20: =J19-J$4 -> 0.0387 | ... U20: =U19-U$4 -> 0.029625199 | AC20: =AC19/(AC15)^AB15 -> -1106823.2 | AD20: =AD19/(AD15)^AC15 -> -223204.84 | AE20: =AE19/(AE15)^AD15 -> 408891.23 | AF20: =AF19/(AF15)^AE15 -> 46018.689 | AG20: =AG19/(AG15)^AF15 -> 512.26628 | AH20: =SUM(AC20:AG20) -> -874605.87
B21: % of IEA | C21: =C17/(SUM(C$5,C$11,C$17,C$23)) -> 0.71512574 | D21: =D17/(SUM(D$5,D$11,D$17,D$23)) -> 0.77340008 | E21: =E17/(SUM(E$5,E$11,E$17,E$23)) -> 0.72382476 | F21: =F17/(SUM(F$5,F$11,F$17,F$23)) -> 0.72926298 | G21: =G17/(SUM(G$5,G$11,G$17,G$23)) -> 0.74565937 | H21: =H17/(SUM(H$5,H$11,H$17,H$23)) -> 0.78887363 | I21: =I17/(SUM(I$5,I$11,I$17,I$23)) -> 0.78464714 | J21: =J17/(SUM(J$5,J$11,J$17,J$23)) -> 0.77531615 | ... P21: =P17/(SUM(P$5,P$11,P$17,P$23)) -> 0.76412367 | Q21: 0.77 | R21: 0.8 | S21: 0.8 | T21: 0.8 | U21: 0.8
B22: Loan Interest Earned (+) | C22: =C17*C19 -> 587163 | D22: =D17*D19 -> 998589 | E22: =E17*E19 -> 945798 | F22: =F17*F19 -> 945530 | G22: =G17*G19 -> 979394 | H22: =H17*H19 -> 1058294.5 | I22: =I17*I19 -> 969031.62 | J22: =J17*J19 -> 1036111 | ... U22: =U17*U19 -> 2945836.1
B23: Securities | C23: =CW51 -> 2706793 | D23: =CT51 -> 2658744 | E23: =CO51 -> 3314445 | F23: =CL51 -> 2647305 | G23: =CI51 -> 2863937 | H23: =CD50 -> 2637149 | I23: =CA50 -> 2925115 | J23: =BX50 -> 3430346 | K23: =BS50 -> 3100286 | L23: =BP50 -> 2846843 | M23: =BM50 -> 2927330 | N23: =BE50 -> 4102828 | O23: =BB50 -> 8360638 | P23: =AY50 -> 9464290 | Q23: =Q$17*Q27/Q$21 -> 9534743.1 | R23: =R$17*R27/R$21 -> 7456467.1 | S23: =S$17*S27/S$21 -> 6263432.3 | T23: =T$17*T27/T$21 -> 6576604 | U23: =U$17*U27/U$21 -> 6741019.1
B24: Growth | D24: =D23/C23-1 -> -0.017751265 | E24: =E23/D23-1 -> 0.24662058 | F24: =F23/E23-1 -> -0.20128257 | G24: =G23/F23-1 -> 0.081831145 | H24: =H23/G23-1 -> -0.079187496 | I24: =I23/H23-1 -> 0.10919595 | J24: =J23/I23-1 -> 0.17272176 | K24: =K23/J23-1 -> -0.096217699 | ... U24: =U23/T23-1 -> 0.025
B25: Yield | C25: =CY51 -> 0.043972701 | D25: =CV51 -> 0.02760702 | E25: =CQ51 -> 0.028016455 | F25: =CN51 -> 0.02374377 | G25: =CK51 -> 0.017708141 | H25: =CF50 -> 0.019322382 | I25: =CC50 -> 0.016222268 | J25: =BZ50 -> 0.016565676 | K25: =BU50 -> 0.019738179 | L25: =BR50 -> 0.022501065 | M25: =BO50 -> 0.024017108 | N25: 0.0205 | O25: =BD50 -> 0.017470437 | P25: =BA50 -> 0.02134867 | Q25: ='Misc Data + Calculations'!AY579 -> 0.03 | R25: ='Misc Data + Calculations'!AZ579 -> 0.0325 | S25: ='Misc Data + Calculations'!BA579 -> 0.029906824 | T25: ='Misc Data + Calculations'!BB579 -> 0.026483065 | U25: ='Misc Data + Calculations'!BC579 -> 0.023028017
B26: Delta to FFR | C26: =C25-C$4 -> 0.042372701 | D26: =D25-D$4 -> 0.02580702 | E26: =E25-E$4 -> 0.027016455 | F26: =F25-F$4 -> 0.02234377 | G26: =G25-G$4 -> 0.016608141 | H26: =H25-H$4 -> 0.018422382 | I26: =I25-I$4 -> 0.014922268 | J26: =J25-J$4 -> 0.012565676 | ... U26: =U25-U$4 -> -0.0019719826
B27: % of IEA | C27: =C23/(SUM(C$5,C$11,C$17,C$23)) -> 0.2096532 | D27: =D23/(SUM(D$5,D$11,D$17,D$23)) -> 0.14999531 | E27: =E23/(SUM(E$5,E$11,E$17,E$23)) -> 0.17090579 | F27: =F23/(SUM(F$5,F$11,F$17,F$23)) -> 0.13342478 | G27: =G23/(SUM(G$5,G$11,G$17,G$23)) -> 0.1312068 | H27: =H23/(SUM(H$5,H$11,H$17,H$23)) -> 0.10222071 | I27: =I23/(SUM(I$5,I$11,I$17,I$23)) -> 0.10303117 | J27: =J23/(SUM(J$5,J$11,J$17,J$23)) -> 0.10960701 | ... P27: =P23/(SUM(P$5,P$11,P$17,P$23)) -> 0.15957578 | Q27: 0.15 | R27: 0.125 | S27: 0.1 | T27: 0.1 | U27: 0.1
B28: Securities Interest Earned (+) | C28: =C23*C25 -> 119025 | D28: =D23*D25 -> 73400 | E28: =E23*E25 -> 92859 | F28: =F23*F25 -> 62857 | G28: =G23*G25 -> 50715 | H28: =H23*H25 -> 50956 | I28: =I23*I25 -> 47452 | J28: =J23*J25 -> 56826 | ... U28: =U23*U25 -> 155232.3
A29: x | B29: Total Interest Income | C29: =SUM(C28,C22,C16,C10) -> 723138.96 | D29: =SUM(D28,D22,D16,D10) -> 1095581.4 | E29: =SUM(E28,E22,E16,E10) -> 1080500.7 | F29: =SUM(F28,F22,F16,F10) -> 1051084.7 | G29: =SUM(G28,G22,G16,G10) -> 1068598.2 | H29: =SUM(H28,H22,H16,H10) -> 1152838.1 | I29: =SUM(I28,I22,I16,I10) -> 1054235.8 | J29: =SUM(J28,J22,J16,J10) -> 1138284.5 | ... U29: =SUM(U28,U22,U16,U10) -> 3272208
B30: LTD Ratio | C30: =C17/C31 -> 0.97824942 | D30: =D17/D31 -> 0.92063628 | E30: =E17/E31 -> 0.8335435 | F30: =F17/F31 -> 0.82458099 | G30: =G17/G31 -> 0.83916781 | H30: =H17/H31 -> 0.88717718 | I30: =I17/I31 -> 0.86492215 | J30: =J17/J31 -> 0.85132897 | ... P30: =P17/P31 -> 0.83461896 | Q30: 0.9 | R30: 0.9 | S30: 0.9 | T30: 0.9 | U30: 0.9
B31: Deposits | C31: =C33+C35 -> 9438139 | D31: =D33+D35 -> 14890695 | E31: =E33+E35 -> 16840664 | F31: =F33+F35 -> 17547625 | G31: =G33+G35 -> 19395402 | H31: =H33+H35 -> 22939970 | I31: =I33+I35 -> 25755600 | J31: =J33+J35 -> 28502372 | ... P31: =P33+P35 -> 54299579 | Q31: =Q17/Q30 -> 54383350 | R31: =R17/R30 -> 53023766 | S31: =S17/S30 -> 55674954 | T31: =T17/T30 -> 58458702 | U31: =U17/U30 -> 59920169
B32: Deposit Growth | D32: =D31/C31-1 -> 0.57771516 | E32: =E31/D31-1 -> 0.13095218 | F32: =F31/E31-1 -> 0.041979402 | G32: =G31/F31-1 -> 0.10530069 | H32: =H31/G31-1 -> 0.18275301 | I32: =I31/H31-1 -> 0.12273904 | J32: =J31/I31-1 -> 0.10664756 | K32: =K31/J31-1 -> 0.08109511 | ... U32: =U31/T31-1 -> 0.025
B33: NIB Deposits | C33: =CW82 -> 1459871 | D33: =CT82 -> 2418816 | E33: =CO82 -> 3087777 | F33: =CL82 -> 3902534 | G33: =CI82 -> 5179687 | H33: =CD75 -> 6834871 | I33: =CA75 -> 7928460 | J33: =BX75 -> 9371481 | K33: =BS75 -> 10627718 | L33: =BP75 -> 11089537 | M33: =BM75 -> 10502618 | N33: =BE84 -> 13823152 | O33: =BB84 -> 21271410 | P33: =AY84 -> 22784258 | Q33: =Q34*Q31 -> 16315005 | R33: =R34*R31 -> 18558318 | S33: =S34*S31 -> 20878108 | T33: =T34*T31 -> 21922013 | U33: =U34*U31 -> 23968068
B34: NIB % of Deposits | C34: =C33/SUM(C33,C35) -> 0.15467784 | D34: =D33/SUM(D33,D35) -> 0.16243809 | E34: =E33/SUM(E33,E35) -> 0.18335245 | F34: =F33/SUM(F33,F35) -> 0.22239671 | G34: =G33/SUM(G33,G35) -> 0.26705747 | H34: =H33/SUM(H33,H35) -> 0.29794594 | I34: =I33/SUM(I33,I35) -> 0.30783441 | J34: =J33/SUM(J33,J35) -> 0.32879653 | ... P34: =P33/SUM(P33,P35) -> 0.41960285 | Q34: 0.3 | R34: 0.35 | S34: 0.375 | T34: 0.375 | U34: 0.4
B35: IB Deposits | C35: =CW75 -> 7978268 | D35: =CT75 -> 12471879 | E35: =CO75 -> 13752887 | F35: =CL75 -> 13645091 | G35: =CI75 -> 14215715 | H35: =CD72 -> 16105099 | I35: =CA72 -> 17827140 | J35: =BX72 -> 19130891 | K35: =BS72 -> 20186057 | L35: =BP72 -> 22140712 | M35: =BM72 -> 25544452 | N35: =BE78 -> 26939739 | O35: =BB78 -> 30212286 | P35: =AY78 -> 31515321 | Q35: =Q31-Q33 -> 38068345 | R35: =R31-R33 -> 34465448 | S35: =S31-S33 -> 34796846 | T35: =T31-T33 -> 36536689 | U35: =U31-U33 -> 35952102
B36: IB % of Deposits | C36: =1-C34 -> 0.84532216 | D36: =1-D34 -> 0.83756191 | E36: =1-E34 -> 0.81664755 | F36: =1-F34 -> 0.77760329 | G36: =1-G34 -> 0.73294253 | H36: =1-H34 -> 0.70205406 | I36: =1-I34 -> 0.69216559 | J36: =1-J34 -> 0.67120347 | ... U36: =1-U34 -> 0.6 | AY36: Year Ended December 31,
B37: Cost of IB | C37: =CY75 -> 0.01622871 | D37: =CV75 -> 0.009360017 | E37: =CQ75 -> 0.0077881829 | F37: =CN75 -> 0.0055620736 | G37: =CK75 -> 0.0044666061 | H37: =CF72 -> 0.0040661656 | I37: =CC72 -> 0.0041232076 | J37: =BZ72 -> 0.0044025132 | K37: =BU72 -> 0.0057659106 | L37: =BR72 -> 0.01060273 | M37: =BO72 -> 0.014711688 | N37: =BH78 -> 0.0068576017 | O37: =BD78 -> 0.0022891019 | P37: =BA78 -> 0.0079909705 | Q37: ='Misc Data + Calculations'!AY581 -> 0.0309 | R37: ='Misc Data + Calculations'!AZ581 -> 0.0325 | S37: ='Misc Data + Calculations'!BA581 -> 0.028610236 | T37: ='Misc Data + Calculations'!BB581 -> 0.023697249 | U37: ='Misc Data + Calculations'!BC581 -> 0.019059845 | AY37: 2022 | BB37: 2021 | BE37: 2020 | BM37: Year Ended December 31, | BX37: Year Ended December 31,
B38: Delta to FFR | C38: =C37-C$4 -> 0.01462871 | D38: =D37-D$4 -> 0.007560017 | E38: =E37-E$4 -> 0.0067881829 | F38: =F37-F$4 -> 0.0041620736 | G38: =G37-G$4 -> 0.0033666061 | H38: =H37-H$4 -> 0.0031661656 | I38: =I37-I$4 -> 0.0028232076 | J38: =J37-J$4 -> 0.00040251319 | ... U38: =U37-U$4 -> -0.0059401553 | AX38: ($ in thousands) | AY38: Average Balance | AZ38: Interest | BA38: Average Yield/ Rate | BB38: Average Balance | BC38: Interest | BD38: Average Yield/ Rate | BE38: Average Balance | BG38: Interest | BH38: Average Yield/ Rate | BM38: 2019 | BP38: 2018 | BS38: 2017 | BX38: 2016 | CA38: 2015 | CD38: 2014 | CI38: 2013 | CL38: 2012 | CO38: 2011 | CT38: 2010 | CW38: 2009
B39: Blended Cost of Deposits | C39: =(C37*C35)/(SUM(C33,C35)) -> 0.013718488 | D39: =(D37*D35)/(SUM(D33,D35)) -> 0.0078395938 | E39: =(E37*E35)/(SUM(E33,E35)) -> 0.0063602005 | F39: =(F37*F35)/(SUM(F33,F35)) -> 0.0043250867 | G39: =(G37*G35)/(SUM(G33,G35)) -> 0.0032737656 | H39: =(H37*H35)/(SUM(H33,H35)) -> 0.0028546681 | I39: =(I37*I35)/(SUM(I33,I35)) -> 0.0028539424 | J39: =(J37*J35)/(SUM(J33,J35)) -> 0.0029549821 | ... U39: =(U37*U35)/(SUM(U33,U35)) -> 0.011435907 | AX39: ASSETS | BL39: ($ in thousands) | BM39: Average Balance | BN39: Interest | BO39: Average Yield/ Rate | BP39: Average Balance | BQ39: Interest | BR39: Average Yield/ Rate | BS39: Average Balance | BT39: Interest | BU39: Average Yield/ Rate | BW39: ($ in thousands) | BX39: Average Balance | BY39: Interest | BZ39: Average Yield/ Rate | CA39: Average Balance | CB39: Interest | CC39: Average Yield/ Rate | CD39: Average Balance | CE39: Interest | CF39: Average Yield/ Rate | CI39: Average Balance | CJ39: Interest | CK39: Average Yield Rate | CL39: Average Balance | CM39: Interest | CN39: Average Yield Rate | CO39: Average Balance | CP39: Interest | CQ39: Average Yield Rate | CT39: Average Balance | CU39: Interest | CV39: Average Yield Rate | CW39: Average Balance | CX39: Interest | CY39: Average Yield Rate
B40: % of IBL | C40: =C35/SUM(C35,C42,C48) -> 0.75337475 | D40: =D35/SUM(D35,D42,D48) -> 0.82423658 | E40: =E35/SUM(E35,E42,E48) -> 0.87442876 | F40: =F35/SUM(F35,F42,F48) -> 0.89682229 | G40: =G35/SUM(G35,G42,G48) -> 0.90583879 | H40: =H35/SUM(H35,H42,H48) -> 0.91254056 | I40: =I35/SUM(I35,I42,I48) -> 0.94918789 | J40: =J35/SUM(J35,J42,J48) -> 0.95906622 | ... P40: =P35/SUM(P35,P42,P48) -> 0.97501997 | Q40: 0.89 | R40: =AVERAGE(S40,Q40) -> 0.92 | S40: 0.95 | T40: 0.975 | U40: 0.975 | AX40: Interest-earning assets: | BL40: ASSETS | BW40: ASSETS | CI40: (Dollars in thousands)
B41: Deposit Interest Expense (-) | C41: =C39*C31 -> 129477 | D41: =D39*D31 -> 116737 | E41: =E39*E31 -> 107110 | F41: =F39*F31 -> 75895 | G41: =G39*G31 -> 63496 | H41: =H39*H31 -> 65486 | I41: =I39*I31 -> 73505 | J41: =J39*J31 -> 84224 | ... U41: =U39*U31 -> 685241.47 | AX41: Interest-bearing cash and deposits with banks | AY41: 3127234 | AZ41: 41113 | BA41: 0.0131 | BB41: 6071896 | BC41: 15531 | BD41: 0.0026 | BE41: 4236430 | BG41: 25175 | BH41: 0.0059 | BL41: Interest-earning assets: | BW41: Interest-earning assets: | CH41: ASSETS | CS41: ASSETS
B42: LT Borrowing | C42: =CW91 -> 235570 | D42: =CT91 -> 235570 | E42: =CO91 -> 226808 | F42: =CL91 -> 183285 | G42: =CI91 -> 166690 | H42: =CD86 -> 237738 | I42: =CA86 -> 218353 | J42: =BX86 -> 198589 | K42: =BS89 -> 178882 | L42: =BP89 -> 159185 | M42: =BM89 -> 152445 | N42: =BE93 -> 734921 | O42: =BB93 -> 151955 | P42: =AY93 -> 152325 | Q42: =Q$35*Q46/Q$40 -> 213867.11 | R42: =R$35*R46/R$40 -> 187312.22 | S42: =S$35*S46/S$40 -> 183141.3 | T42: =T$35*T46/T$40 -> 187367.63 | U42: =U$35*U46/U$40 -> 184369.75
...

Sheet IEA Yield + IBL Cost Build
B2: East West Bancorp Net Income Build ($m) | C2: 2009 | D2: 2010 | E2: 2011 | F2: 2012 | G2: 2013 | H2: 2014 | I2: 2015 | J2: 2016 | K2: 2017 | L2: 2018 | M2: 2019 | N2: 2020 | O2: 2021 | P2: 2022 | Q2: 2023 | R2: 2024 | S2: 2025 | T2: 2026 | U2: 2027
B3: Average FFR | C3: 0.0016 | D3: 0.0018 | E3: 0.001 | F3: 0.0014 | G3: 0.0011 | H3: 0.0009 | I3: 0.0013 | J3: 0.004 | K3: 0.01 | L3: 0.0183 | M3: 0.0216 | N3: 0.0038 | O3: 0.0008 | P3: 0.0168 | Q3: 0.0508 | R3: 0.0488 | S3: 0.0418 | T3: 0.0338 | U3: 0.025
D4: =ROUND(((D3-C3)/C3),3) -> 0.125 | E4: =ROUND(((E3-D3)/D3),3) -> -0.444 | F4: =ROUND(((F3-E3)/E3),3) -> 0.4 | G4: =ROUND(((G3-F3)/F3),3) -> -0.214 | H4: =ROUND(((H3-G3)/G3),3) -> -0.182 | I4: =ROUND(((I3-H3)/H3),3) -> 0.444 | J4: =ROUND(((J3-I3)/I3),3) -> 2.077 | K4: =ROUND(((K3-J3)/J3),3) -> 1.5 | ... P4: =ROUND(((P3-O3)/O3),3) -> 20
B5: Cash and Cash with Banks Yield % | C5: ='Net Income Build'!C7 -> 0.0103 | D5: ='Net Income Build'!D7 -> 0.0116 | E5: ='Net Income Build'!E7 -> 0.0222 | F5: ='Net Income Build'!F7 -> 0.0153 | G5: ='Net Income Build'!G7 -> 0.0146 | H5: ='Net Income Build'!H7 -> 0.0158 | I5: ='Net Income Build'!I7 -> 0.0097 | J5: ='Net Income Build'!J7 -> 0.0078 | ... P5: ='Net Income Build'!P7 -> 0.0131
B6: Implied beta to FFR | D6: =ROUND(((D5-C5)/C5),3) -> 0.126 | E6: =ROUND(((E5-D5)/D5),3) -> 0.914 | F6: =ROUND(((F5-E5)/E5),3) -> -0.311 | G6: =ROUND(((G5-F5)/F5),3) -> -0.046 | H6: =ROUND(((H5-G5)/G5),3) -> 0.082 | I6: =ROUND(((I5-H5)/H5),3) -> -0.386 | J6: =ROUND(((J5-I5)/I5),3) -> -0.196 | K6: =ROUND(((K5-J5)/J5),3) -> 0.91 | ... P6: =ROUND(((P5-O5)/O5),3) -> 4.038
B7: Repo Yield | C7: ='Net Income Build'!C13 -> 0.0876 | D7: ='Net Income Build'!D13 -> 0.0264 | E7: ='Net Income Build'!E13 -> 0.0188 | F7: ='Net Income Build'!F13 -> 0.0161 | G7: ='Net Income Build'!G13 -> 0.0141 | H7: ='Net Income Build'!H13 -> 0.0152 | I7: ='Net Income Build'!I13 -> 0.0148 | J7: ='Net Income Build'!J13 -> 0.0179 | ... P7: ='Net Income Build'!P13 -> 0.0213
B8: Implied beta to FFR
B9: Loan Yield | C9: ='Net Income Build'!C19 -> 0.063594962 | D9: ='Net Income Build'!D19 -> 0.072842313 | E9: ='Net Income Build'!E19 -> 0.067376882 | F9: ='Net Income Build'!F19 -> 0.065346698 | G9: ='Net Income Build'!G19 -> 0.060174132 | H9: ='Net Income Build'!H19 -> 0.052 | I9: ='Net Income Build'!I19 -> 0.0435 | J9: ='Net Income Build'!J19 -> 0.0427 | ... P9: ='Net Income Build'!P19 -> 0.0452
B10: Implied Composite beta to FFR
B11: Securities Yield | E11: =E9 -> 0.067376882 | F11: =F9 -> 0.065346698 | G11: =G9 -> 0.060174132 | H11: =H9 -> 0.052 | I11: =I9 -> 0.0435 | J11: =J9 -> 0.0427 | K11: =K9 -> 0.044
B12: IB Deposit Cost
B13: Implied Composite beta to FFR
B14: LT Borrowing Cost
B15: Implied Composite beta to FFR
B16: ST Borrowing Cost
B17: Implied Composite beta to FFR

Sheet DCF
B2: East West Bancorp FCFE Build | C2: 2009 | D2: 2010 | E2: 2011 | F2: 2012 | G2: 2013 | H2: 2014 | I2: 2015 | J2: 2016 | K2: 2017 | L2: 2018 | M2: 2019 | N2: 2020 | O2: 2021 | P2: 2022 | Q2: 2023 | R2: 2024 | S2: 2025 | T2: 2026 | U2: 2027 | V2: Steady State
B3: Net Income (+) | C3: ='Net Income Build'!C72 -> 82441.816 | D3: ='Net Income Build'!D72 -> 164397.59 | E3: ='Net Income Build'!E72 -> 245289.72 | F3: ='Net Income Build'!F72 -> 281645.73 | G3: ='Net Income Build'!G72 -> 294966.43 | H3: ='Net Income Build'!H72 -> 345015.06 | I3: ='Net Income Build'!I72 -> 385104.75 | J3: ='Net Income Build'!J72 -> 432473.23 | ... U3: ='Net Income Build'!U72 -> 1254108.3 | V3: =U3*(1+0.02) -> 1279190.5
B4: Assets | C4: 13838945 | D4: =20178109 -> 20178109 | E4: =21573121 -> 21573121 | F4: =21830543 -> 21830543 | G4: 23560692 | H4: 27652970 | I4: 30328457 | J4: 33169373 | K4: 35787613 | L4: 38542569 | M4: 42484885 | N4: 48937793 | O4: 59251091 | P4: 62838282 | Q4: =Q5/Q6 -> 66910478 | R4: =R5/R6 -> 62791302 | S4: =S5/S6 -> 65930867 | T4: =T5/T6 -> 69227410 | U4: =U5/U6 -> 70958095 | V4: =V5/V6 -> 72377257
B5: IEAs | C5: =SUM('Net Income Build'!C5,'Net Income Build'!C11,'Net Income Build'!C17,'Net Income Build'!C23) -> 12910812 | D5: =SUM('Net Income Build'!D5,'Net Income Build'!D11,'Net Income Build'!D17,'Net Income Build'!D23) -> 17725514 | E5: =SUM('Net Income Build'!E5,'Net Income Build'!E11,'Net Income Build'!E17,'Net Income Build'!E23) -> 19393404 | F5: =SUM('Net Income Build'!F5,'Net Income Build'!F11,'Net Income Build'!F17,'Net Income Build'!F23) -> 19841180 | G5: =SUM('Net Income Build'!G5,'Net Income Build'!G11,'Net Income Build'!G17,'Net Income Build'!G23) -> 21827657 | H5: =SUM('Net Income Build'!H5,'Net Income Build'!H11,'Net Income Build'!H17,'Net Income Build'!H23) -> 25798578 | I5: =SUM('Net Income Build'!I5,'Net Income Build'!I11,'Net Income Build'!I17,'Net Income Build'!I23) -> 28390582 | J5: =SUM('Net Income Build'!J5,'Net Income Build'!J11,'Net Income Build'!J17,'Net Income Build'!J23) -> 31296775 | ... U5: =SUM('Net Income Build'!U5,'Net Income Build'!U11,'Net Income Build'!U17,'Net Income Build'!U23) -> 67410191 | V5: =U5*(1+0.02) -> 68758394
B6: % of total assets | C6: =C5/C4 -> 0.93293325 | D6: =D5/D4 -> 0.87845268 | E6: =E5/E4 -> 0.89896144 | F6: =F5/F4 -> 0.90887249 | G6: =G5/G4 -> 0.9264438 | H6: =H5/H4 -> 0.93294058 | I6: =I5/I4 -> 0.93610374 | J6: =J5/J4 -> 0.94354437 | ... P6: =P5/P4 -> 0.94383647 | Q6: 0.95 | R6: 0.95 | S6: 0.95 | T6: 0.95 | U6: 0.95 | V6: 0.95
B7: CET 1 Ratio | C7: 0.179 | D7: 0.157 | E7: 0.148 | F7: 0.148 | G7: 0.119 | H7: 0.11 | I7: 0.107 | J7: 0.109 | K7: 0.114 | L7: 0.122 | M7: 0.129 | N7: 0.127 | O7: 0.128 | P7: 0.127 | Q7: =P7+($U$7-$P$7)/10 -> 0.1273 | R7: =Q7+($U$7-$P$7)/5 -> 0.1279 | S7: =R7+($U$7-$P$7)/10 -> 0.1282 | T7: =S7+($U$7-$P$7)/10 -> 0.1285 | U7: 0.13 | V7: =U7 -> 0.13
B8: CET 1 Capital | C8: 2011158 | D8: 1865602 | E8: 2074963 | F8: 2116757 | G8: 2102476 | H8: 2405452 | I8: 2686627 | J8: 2976002 | K8: 3390070 | L8: 3966842 | M8: 4546592 | N8: 4882555 | O8: 5559357 | P8: 6347108 | Q8: =Q9*Q7 -> 6814163.1 | R8: =R9*R7 -> 6424806 | S8: =S9*S7 -> 6761869.7 | T8: =T9*T7 -> 7116577.8 | U8: =U9*U7 -> 7379641.9 | V8: =U8*(1+0.02) -> 7527234.8
B9: Implied RWAs | C9: =C8/C7 -> 11235520 | D9: =D8/D7 -> 11882815 | E9: =E8/E7 -> 14020020 | F9: =F8/F7 -> 14302412 | G9: =G8/G7 -> 17667866 | H9: =H8/H7 -> 21867745 | I9: =I8/I7 -> 25108664 | J9: =J8/J7 -> 27302771 | ... P9: =P8/P7 -> 49977228 | Q9: =Q10*Q4 -> 53528382 | R9: =R10*R4 -> 50233041 | S9: =S10*S4 -> 52744693 | T9: =T10*T4 -> 55381928 | U9: =U10*U4 -> 56766476 | V9: =V10*V4 -> 57901806
B10: Implied Risk Weighting % | C10: =C9/C4 -> 0.81187688 | D10: =D9/D4 -> 0.58889638 | E10: =E9/E4 -> 0.64988373 | F10: =F9/F4 -> 0.65515604 | G10: =G9/G4 -> 0.74988738 | H10: =H9/H4 -> 0.79079193 | I10: =I9/I4 -> 0.82789123 | J10: =J9/J4 -> 0.82313195 | ... P10: =P9/P4 -> 0.79533092 | Q10: 0.8 | R10: 0.8 | S10: 0.8 | T10: 0.8 | U10: 0.8 | V10: 0.8
B11: CET 1 YoY Delta (-) | D11: =D8-C8 -> -145556 | E11: =E8-D8 -> 209361 | F11: =F8-E8 -> 41794 | G11: =G8-F8 -> -14281 | H11: =H8-G8 -> 302976 | I11: =I8-H8 -> 281175 | J11: =J8-I8 -> 289375 | K11: =K8-J8 -> 414068 | ... V11: =V8-U8 -> 147592.84
B12: FCFE | C12: =C3-C11 -> 82441.816 | D12: =D3-D11 -> 309953.59 | E12: =E3-E11 -> 35928.721 | F12: =F3-F11 -> 239851.73 | G12: =G3-G11 -> 309247.43 | H12: =H3-H11 -> 42039.062 | I12: =I3-I11 -> 103929.75 | J12: =J3-J11 -> 143098.23 | ... V12: =V3-V11 -> 1131597.6
B13: NPV of Stage 1 FCFE | Q13: =Q12/Q15 -> 607513.55 | R13: =R12/R15 -> 1254857.8 | S13: =S12/S15 -> 638520.99 | T13: =T12/T15 -> 655031.43 | U13: =U12/U15 -> 703606.55
Q14: 0.5 | R14: =Q14+1 -> 1.5 | S14: =R14+1 -> 2.5 | T14: =S14+1 -> 3.5 | U14: =T14+1 -> 4.5
Q15: =(1+$D$23)^Q14 -> 1.0387935 | R15: =(1+$D$23)^R14 -> 1.1209538 | S15: =(1+$D$23)^S14 -> 1.2096123 | T15: =(1+$D$23)^T14 -> 1.3052829 | U15: =(1+$D$23)^U14 -> 1.4085204
B16: Discount Rate | P16: Implied ROE | Q16: =Q3/Q17 -> 0.16206129 | R16: =R3/R17 -> 0.15928113 | S16: =S3/S17 -> 0.16500087 | T16: =T3/T17 -> 0.17089985 | U16: =U3/U17 -> 0.17082374 | V16: =(V12/(D23-0.02))/U15 -> 13595657
B17: Tax Rate | D17: 0.23 | P17: 6309000 | Q17: =P17+Q11 -> 6776055.1 | R17: =Q17+R11 -> 6386698 | S17: =R17+S11 -> 6723761.7 | T17: =S17+T11 -> 7078469.8 | U17: =T17+U11 -> 7341533.9
B19: Risk Free Rate | D19: 0.0423 | S19: =U3*15.2 -> 19062446
B20: Un-levered Beta | D20: 0.84 | S20: =(S19/7600000)^(1/5) -1 -> 0.20191293
B21: ERP | D21: 0.0438
F22: =F11/F3 -> 0.1483921 | G22: =G11/G3 -> -0.048415678 | H22: =H11/H3 -> 0.87815297 | I22: =I11/I3 -> 0.73012602 | J22: =J11/J3 -> 0.66911656 | K22: =K11/K3 -> 0.81779376 | L22: =L11/L3 -> 0.82093864 | M22: =M11/M3 -> 0.85839151 | ... P22: =P11/P3 -> 0.69830383
B23: Cost of Equity | D23: =SUM(D19,(D20*D21)) -> 0.079092 | L23: =AVERAGE(F22:P22) -> 0.63078842
B25: Perpetuity Growth Method
B26: Growth Rate | D26: 0.02
B27: Stage 2 FCF | D27: =U12*(1+D26)/(D23-D26) -> 17106631
B28: Cumulative PV of Stage 1 FCF | D28: =SUM(Q13:U13) -> 3859530.3
B29: PV of Stage 2 FCF | D29: =D27/U15 -> 12145107
B30: Equity Value | D30: =SUM(D28:D29) -> 16004638
B31: Diluted Shares Outstanding | D31: 141876
B32: Intrinsic Stock Price | D32: =D30/D31 -> 112.80722
B33: Current Stock Price | D33: 56.99
B34: Margin of Safety | D34: =D32/D33-1 -> 0.97942136
B35: Implied IRR | D35: =((D30*(1+D23)^5)/(D33*D31))^(1/5) -1 -> 0.23698981
B36: Implied Terminal Multiple ('27 Earnings) | D36: =D30/'Net Income Build'!U72 -> 12.761767
