Workbook

Sheet Cover Page
A1: Starbucks Corporation
A2: Ticker | B2: NYSE: SBUX
A3: Current Price | B3: 85.4
A4: Target Price | B4: =DCF!G23 -> 108.07954
A5: Implied Upside | B5: =DCF!G25 -> 0.26556836

Sheet Income Statement
A1: Fiscal Year | B1: 2014A | C1: 2015A | D1: 1Q 2016 | E1: 2Q 2016 | F1: 3Q 2016 | G1: 4Q 2016 | H1: 2016A | I1: 1Q 2017 | J1: 2Q 2017 | K1: 3Q 2017 | L1: 4Q 2017 | M1: 2017A | N1: 1Q 2018 | O1: 2Q 2018 | P1: 3Q 2018 | Q1: 4Q 2018 | R1: 2018A | S1: 2019E | T1: 2020E | U1: 2021E | V1: 2022E | W1: 2023E | X1: 2024E
A2: Net revenues:
A3: Company-operated stores | B3: 12977.9 | C3: 15197.3 | D3: 4210.6 | E3: 3944.2 | F3: 4181.6 | G3: =H3-SUM(D3:F3) -> 4507.7 | H3: 16844.1 | I3: 4469.3 | J3: 4195.4 | K3: 4509 | L3: =M3-SUM(I3:K3) -> 4477 | M3: 17650.7 | N3: 4741.8 | O3: 4828 | P3: 5060.4 | Q3: =R3-SUM(N3:P3) -> 5060.1 | R3: 19690.3 | S3: ='Revenue Build'!K3 -> 21544.4 | T3: ='Revenue Build'!P3 -> 23837.985 | U3: ='Revenue Build'!U3 -> 25935.549 | V3: ='Revenue Build'!Z3 -> 28143.533 | W3: ='Revenue Build'!AE3 -> 30448.303 | X3: ='Revenue Build'!AJ3 -> 32897.494
A4: Y/y growth | C4: =C3/B3-1 -> 0.1710138 | H4: =H3/C3-1 -> 0.10836135 | I4: =I3/D3-1 -> 0.061440175 | J4: =J3/E3-1 -> 0.063688454 | K4: =K3/F3-1 -> 0.078295389 | L4: =L3/G3-1 -> -0.0068105686 | M4: =M3/H3-1 -> 0.047886203 | N4: =N3/I3-1 -> 0.060971517 | O4: =O3/J3-1 -> 0.15078419 | ... R4: =R3/M3-1 -> 0.11555349 | S4: =S3/R3-1 -> 0.094163116 | T4: =T3/S3-1 -> 0.10645853 | U4: =U3/T3-1 -> 0.087992511 | V4: =V3/U3-1 -> 0.085133504 | W4: =W3/V3-1 -> 0.08189341 | X4: =X3/W3-1 -> 0.080437686
A5: Licensed stores | B5: 1588.6 | C5: 1861.9 | D5: 540.6 | E5: 493.1 | F5: 527.2 | G5: =H5-SUM(D5:F5) -> 593.3 | H5: 2154.2 | I5: 602.4 | J5: 546.7 | K5: 588.3 | L5: =M5-SUM(I5:K5) -> 617.6 | M5: 2355 | N5: 682.4 | O5: 625.6 | P5: 660.6 | Q5: =R5-SUM(N5:P5) -> 683.6 | R5: 2652.2 | S5: ='Revenue Build'!K5 -> 2875 | T5: ='Revenue Build'!P5 -> 3284.9718 | U5: ='Revenue Build'!U5 -> 3546.7617 | V5: ='Revenue Build'!Z5 -> 3817.7241 | W5: ='Revenue Build'!AE5 -> 4098.1189 | X5: ='Revenue Build'!AJ5 -> 4388.2136
A6: Y/y growth | C6: =C5/B5-1 -> 0.17203827 | H6: =H5/C5-1 -> 0.15699017 | I6: =I5/D5-1 -> 0.11431743 | J6: =J5/E5-1 -> 0.10870006 | K6: =K5/F5-1 -> 0.1158953 | L6: =L5/G5-1 -> 0.040957357 | M6: =M5/H5-1 -> 0.093213258 | N6: =N5/I5-1 -> 0.13280212 | O6: =O5/J5-1 -> 0.14432047 | ... R6: =R5/M5-1 -> 0.12619958 | S6: =S5/R5-1 -> 0.084005731 | T6: =T5/S5-1 -> 0.14259888 | U6: =U5/T5-1 -> 0.079693209 | V6: =V5/U5-1 -> 0.076397111 | W6: =W5/V5-1 -> 0.073445558 | X6: =X5/W5-1 -> 0.070787267
A7: CPG, foodservice and other | B7: 1881.3 | C7: 2103.5 | D7: 622.3 | E7: 555.9 | F7: 529.2 | G7: =H7-SUM(D7:F7) -> 610.2 | H7: 2317.6 | I7: 661.2 | J7: 551.9 | K7: 564.2 | L7: =M7-SUM(I7:K7) -> 603.8 | M7: 2381.1 | N7: 649.5 | O7: 578.2 | P7: 589.3 | Q7: =R7-SUM(N7:P7) -> 560 | R7: 2377 | S7: ='Revenue Build'!K7 -> 2089.2 | T7: ='Revenue Build'!P7 -> 2110.092 | U7: ='Revenue Build'!U7 -> 2131.1929 | V7: ='Revenue Build'!Z7 -> 2152.5048 | W7: ='Revenue Build'!AE7 -> 2174.0299 | X7: ='Revenue Build'!AJ7 -> 2195.7702
A8: Y/y growth | C8: =C7/B7-1 -> 0.11810982 | H8: =H7/C7-1 -> 0.10178274 | I8: =I7/D7-1 -> 0.062510043 | J8: =J7/E7-1 -> -0.0071955388 | K8: =K7/F7-1 -> 0.066137566 | L8: =L7/G7-1 -> -0.010488364 | M8: =M7/H7-1 -> 0.027399033 | N8: =N7/I7-1 -> -0.0176951 | O8: =O7/J7-1 -> 0.04765356 | ... R8: =R7/M7-1 -> -0.0017218932 | S8: =S7/R7-1 -> -0.12107699 | T8: =T7/S7-1 -> 0.01 | U8: =U7/T7-1 -> 0.01 | V8: =V7/U7-1 -> 0.01 | W8: =W7/V7-1 -> 0.01 | X8: =X7/W7-1 -> 0.01
A9: Total net revenues | B9: =B3+B5+B7 -> 16447.8 | C9: =C3+C5+C7 -> 19162.7 | D9: 5373.5 | E9: 4993.2 | F9: 5238 | G9: =H9-SUM(D9:F9) -> 5711.2 | H9: =H3+H5+H7 -> 21315.9 | I9: 5732.9 | J9: 5294 | K9: 5661.5 | L9: =M9-SUM(I9:K9) -> 5698.4 | M9: =M3+M5+M7 -> 22386.8 | N9: 6073.7 | O9: 6031.8 | P9: 6310.3 | Q9: =R9-SUM(N9:P9) -> 6303.7 | R9: =R3+R5+R7 -> 24719.5 | S9: ='Revenue Build'!K9 -> 26508.6 | T9: ='Revenue Build'!P9 -> 29233.049 | U9: ='Revenue Build'!U9 -> 31613.504 | V9: ='Revenue Build'!Z9 -> 34113.762 | W9: ='Revenue Build'!AE9 -> 36720.452 | X9: ='Revenue Build'!AJ9 -> 39481.478
A10: Y/y growth | C10: =C9/B9-1 -> 0.16506159 | H10: =H9/C9-1 -> 0.11236412 | I10: =I9/D9-1 -> 0.066883782 | J10: =J9/E9-1 -> 0.060241929 | K10: =K9/F9-1 -> 0.08085147 | L10: =L9/G9-1 -> -0.0022412103 | M10: =M9/H9-1 -> 0.050239493 | N10: =N9/I9-1 -> 0.059446354 | O10: =O9/J9-1 -> 0.13936532 | ... R10: =R9/M9-1 -> 0.1041998 | S10: =S9/R9-1 -> 0.072376059 | T10: =T9/S9-1 -> 0.10277604 | U10: =U9/T9-1 -> 0.081430269 | V10: =V9/U9-1 -> 0.079088306 | W10: =W9/V9-1 -> 0.076411679 | X10: =X9/W9-1 -> 0.075190414
A12: Cost of sales including occupancy costs | B12: 6858.8 | C12: 7787.5 | D12: 2186.2 | E12: 2010.3 | F12: 2060.3 | G12: =H12-SUM(D12:F12) -> 2254.3 | H12: 8511.1 | I12: 2295 | J12: 2141.2 | K12: 2249.1 | L12: =M12-SUM(I12:K12) -> 2349 | M12: 9034.3 | N12: 2502.9 | O12: 2516 | P12: 2554.9 | Q12: =R12-SUM(N12:P12) -> 2600.7 | R12: 10174.5 | S12: ='Revenue Build'!K69 -> 10926.9 | T12: ='Revenue Build'!P69 -> 11734.94 | U12: ='Revenue Build'!U69 -> 12556.385 | V12: ='Revenue Build'!Z69 -> 13435.332 | W12: ='Revenue Build'!AE69 -> 14375.806 | X12: ='Revenue Build'!AJ69 -> 15382.112
A13: Total cost of products | B13: =B12 -> 6858.8 | C13: =C12 -> 7787.5 | D13: =D12 -> 2186.2 | E13: =E12 -> 2010.3 | F13: =F12 -> 2060.3 | G13: =G12 -> 2254.3 | H13: =H12 -> 8511.1 | I13: =I12 -> 2295 | ... X13: =X12 -> 15382.112
A15: Gross income | B15: =B9-B13 -> 9589 | C15: =C9-C13 -> 11375.2 | D15: =D9-D13 -> 3187.3 | E15: =E9-E13 -> 2982.9 | F15: =F9-F13 -> 3177.7 | G15: =G9-G13 -> 3456.9 | H15: =H9-H13 -> 12804.8 | I15: =I9-I13 -> 3437.9 | ... X15: =X9-X13 -> 24099.366
A16: Gross margin | B16: =B15/B9 -> 0.5829959 | C16: =C15/C9 -> 0.59361155 | D16: =D15/D9 -> 0.59315158 | E16: =E15/E9 -> 0.59739245 | F16: =F15/F9 -> 0.60666285 | G16: =G15/G9 -> 0.60528435 | H16: =H15/H9 -> 0.6007159 | I16: =I15/I9 -> 0.59967905 | ... X16: =X15/X9 -> 0.61039675
A18: Store operating expenses | B18: 4638.2 | C18: 5411.1 | D18: 1506.2 | E18: 1466.4 | F18: 1529.4 | G18: =H18-SUM(D18:F18) -> 1562.3 | H18: 6064.3 | I18: 1638.2 | J18: 1586.4 | K18: 1628.9 | L18: =M18-SUM(I18:K18) -> 1639.8 | M18: 6493.3 | N18: 1737 | O18: 1789.6 | P18: 1825 | Q18: =R18-SUM(N18:P18) -> 1841.6 | R18: 7193.2 | S18: =S19*S9 -> 7687.494 | T18: =T19*T9 -> 8477.5842 | U18: =U19*U9 -> 9167.9161 | V18: =V19*V9 -> 9892.9911 | W18: =W19*W9 -> 10648.931 | X18: =X19*X9 -> 11449.629
A19: % of sales | B19: =B18/B9 -> 0.28199516 | C19: =C18/C9 -> 0.2823767 | D19: =D18/D9 -> 0.28030148 | E19: =E18/E9 -> 0.2936794 | F19: =F18/F9 -> 0.29198167 | G19: =G18/G9 -> 0.27355022 | H19: =H18/H9 -> 0.28449655 | I19: =I18/I9 -> 0.28575416 | ... R19: =R18/R9 -> 0.29099294 | S19: 0.29 | T19: 0.29 | U19: 0.29 | V19: 0.29 | W19: 0.29 | X19: 0.29
A20: Other operating expenses | B20: 457.3 | C20: 522.4 | D20: 146.2 | E20: 139.6 | F20: 137.5 | G20: =H20-SUM(D20:F20) -> 122.1 | H20: 545.4 | I20: 145.4 | J20: 134.7 | K20: 142.5 | L20: =M20-SUM(I20:K20) -> 77.7 | M20: 500.3 | N20: 141.6 | O20: 134.3 | P20: 148 | Q20: =R20-SUM(N20:P20) -> 115.4 | R20: 539.3 | S20: =S21*S9 -> 583.1892 | T20: =T21*T9 -> 643.12708 | U20: =U21*U9 -> 695.49709 | V20: =V21*V9 -> 750.50277 | W20: =W21*W9 -> 807.84995 | X20: =X21*X9 -> 868.59252
A21: % of sales | B21: =B20/B9 -> 0.02780311 | C21: =C20/C9 -> 0.027261294 | D21: =D20/D9 -> 0.027207593 | E21: =E20/E9 -> 0.027958023 | F21: =F20/F9 -> 0.026250477 | G21: =G20/G9 -> 0.021379045 | H21: =H20/H9 -> 0.025586534 | I21: =I20/I9 -> 0.025362382 | ... R21: =R20/R9 -> 0.021816784 | S21: 0.022 | T21: 0.022 | U21: 0.022 | V21: 0.022 | W21: 0.022 | X21: 0.022
A22: Depreciation and amortization expenses | B22: 709.6 | C22: 893.9 | D22: 235.5 | E22: 247.8 | F22: 247.6 | G22: =H22-SUM(D22:F22) -> 249.9 | H22: 980.8 | I22: 249.7 | J22: 253.6 | K22: 252.6 | L22: =M22-SUM(I22:K22) -> 255.5 | M22: 1011.4 | N22: 258.8 | O22: 331.6 | P22: 330 | Q22: =R22-SUM(N22:P22) -> 326.6 | R22: 1247 | S22: ='Balance Sheet'!G26 -> 1359.5147 | T22: ='Balance Sheet'!H26 -> 1548.9449 | U22: ='Balance Sheet'!I26 -> 1753.8004 | V22: ='Balance Sheet'!J26 -> 1974.8576 | W22: ='Balance Sheet'!K26 -> 2212.8061 | X22: ='Balance Sheet'!L26 -> 2468.6461
A23: % of sales | B23: =B22/B9 -> 0.043142548 | C23: =C22/C9 -> 0.046647915 | D23: =D22/D9 -> 0.043826184 | E23: =E22/E9 -> 0.049627493 | F23: =F22/F9 -> 0.04726995 | G23: =G22/G9 -> 0.043756128 | H23: =H22/H9 -> 0.046012601 | I23: =I22/I9 -> 0.043555618 | ... X23: =X22/X9 -> 0.062526688
A24: General and administrative expenses | B24: 991.3 | C24: 1196.7 | D24: 305.5 | E24: 330.5 | F24: 323.4 | G24: =H24-SUM(D24:F24) -> 401.2 | H24: 1360.6 | I24: 356.4 | J24: 326.8 | K24: 325 | L24: =M24-SUM(I24:K24) -> 442.5 | M24: 1450.7 | N24: 379.1 | O24: 405.8 | P24: 468.7 | Q24: =R24-SUM(N24:P24) -> 505.4 | R24: 1759 | S24: =S25*S9 -> 1855.602 | T24: =T25*T9 -> 2046.3134 | U24: =U25*U9 -> 2212.9453 | V24: =V25*V9 -> 2387.9634 | W24: =W25*W9 -> 2570.4317 | X24: =X25*X9 -> 2763.7035
A25: % of sales | B25: =B24/B9 -> 0.060269459 | C25: =C24/C9 -> 0.062449446 | D25: =D24/D9 -> 0.056853075 | E25: =E24/E9 -> 0.066190018 | F25: =F24/F9 -> 0.061741123 | G25: =G24/G9 -> 0.070247934 | H25: =H24/H9 -> 0.063830286 | I25: =I24/I9 -> 0.062167489 | ... R25: =R24/R9 -> 0.071158397 | S25: 0.07 | T25: 0.07 | U25: 0.07 | V25: 0.07 | W25: 0.07 | X25: 0.07
A26: Litigation credit | B26: -20.2 | C26: 0 | G26: =H26-SUM(D26:F26) -> 0 | H26: 0 | I26: - | J26: 0 | K26: 120.2 | L26: =M26-SUM(I26:K26) -> 33.3 | M26: 153.5 | N26: 27.6 | O26: 134.7 | P26: 16.9 | Q26: =R26-SUM(N26:P26) -> 45.2 | R26: 224.4 | S26: 0 | T26: 0 | U26: 0 | V26: 0 | W26: 0
A27: Operating costs (excl. COGS) | B27: =SUM(B18+B20+B22+B24+B26) -> 6776.2 | C27: =SUM(C18+C20+C22+C24+C26) -> 8024.1 | D27: =SUM(D18+D20+D22+D24+D26) -> 2193.4 | E27: =SUM(E18+E20+E22+E24+E26) -> 2184.3 | F27: =SUM(F18+F20+F22+F24+F26) -> 2237.9 | G27: =SUM(G18+G20+G22+G24+G26) -> 2335.5 | H27: =SUM(H18+H20+H22+H24+H26) -> 8951.1 | I27: =SUM(I18+I20+I22+I24+I26) -> #VALUE! | ... X27: =SUM(X18+X20+X22+X24+X26) -> 17550.571
A29: Income from equity investees | B29: 268.3 | C29: 249.9 | D29: 64.1 | E29: 65.6 | F29: 82.5 | G29: =H29-SUM(D29:F29) -> 106 | H29: 318.2 | I29: 84.4 | J29: 84.1 | K29: 101 | L29: =M29-SUM(I29:K29) -> 121.9 | M29: 391.4 | N29: 89.4 | O29: 52.7 | P29: 71.4 | Q29: =R29-SUM(N29:P29) -> 87.7 | R29: 301.2 | S29: =R29*1.01 -> 304.212 | T29: =S29*1.01 -> 307.25412 | U29: =T29*1.01 -> 310.32666 | V29: =U29*1.01 -> 313.42993 | W29: =V29*1.01 -> 316.56423 | X29: =W29*1.01 -> 319.72987
A30: Operating income (EBIT) | B30: =B9-B13-B27+B29 -> 3081.1 | C30: =C9-C13-C27+C29 -> 3601 | D30: =D9-D13-D27+D29 -> 1058 | E30: =E9-E13-E27+E29 -> 864.2 | F30: =F9-F13-F27+F29 -> 1022.3 | G30: =G9-G13-G27+G29 -> 1227.4 | H30: =H9-H13-H27+H29 -> 4171.9 | I30: =I9-I13-I27+I29 -> #VALUE! | ... X30: =X9-X13-X27+X29 -> 6868.5253
A31: EBIT margin | B31: =B30/B9 -> 0.18732596 | C31: =C30/C9 -> 0.18791715 | D31: =D30/D9 -> 0.19689216 | E31: =E30/E9 -> 0.17307538 | F31: =F30/F9 -> 0.19516991 | G31: =G30/G9 -> 0.21491105 | H31: =H30/H9 -> 0.19571775 | I31: =I30/I9 -> #VALUE! | ... X31: =X30/X9 -> 0.17396829
A33: Gain resulting from acquisition of joint venture | B33: 0 | C33: 390.6 | D33: 0 | E33: - | F33: 0 | G33: =H33-SUM(D33:F33) -> 0 | H33: 0 | I33: - | J33: 0 | K33: 0 | L33: =M33-SUM(I33:K33) -> 0 | M33: 0 | N33: 1326.3 | O33: 47.6 | P33: 2.5 | Q33: =R33-SUM(N33:P33) -> 0 | R33: 1376.4 | S33: 0 | T33: 0 | U33: 0 | V33: 0 | W33: 0 | X33: 0
A34: Net gain from divestiture of certain operations | B34: 0 | C34: -61.1 | G34: =H34-SUM(D34:F34) -> 0 | H34: 0 | I34: - | J34: 9.6 | K34: 0 | L34: =M34-SUM(I34:K34) -> 83.9 | M34: 93.5 | N34: 501.2 | O34: -4.9 | P34: 0 | Q34: =R34-SUM(N34:P34) -> 2.9 | R34: 499.2 | S34: 600 | T34: 0 | U34: 0 | V34: 0 | W34: 0 | X34: 0
A35: Interest income and other, net | B35: 142.7 | C35: 43 | D35: 8.1 | E35: 14.5 | F35: 72.9 | G35: =H35-SUM(D35:F35) -> 12.5 | H35: 108 | I35: 24.1 | J35: 58.3 | K35: 31.7 | L35: =M35-SUM(I35:K35) -> 67.7 | M35: 181.8 | N35: 88.2 | O35: 35.5 | P35: 31.5 | Q35: =R35-SUM(N35:P35) -> 36.2 | R35: 191.4 | S35: 191.4 | T35: 191.4 | U35: 191.4 | V35: 191.4 | W35: 191.4 | X35: 191.4
A36: Interest expense | B36: -64.1 | C36: -70.5 | D36: -16.5 | E36: -18.3 | F36: -21.8 | G36: =H36-SUM(D36:F36) -> -24.7 | H36: -81.3 | I36: -23.8 | J36: -22.9 | K36: -23.5 | L36: =M36-SUM(I36:K36) -> -22.3 | M36: -92.5 | N36: -25.9 | O36: -35.1 | P36: -45.4 | Q36: =R36-SUM(N36:P36) -> -63.9 | R36: -170.3 | S36: =R36*(1+S37) -> -195.845 | T36: =S36*(1+T37) -> -225.22175 | U36: =T36*(1+U37) -> -259.00501 | V36: =U36*(1+V37) -> -297.85576 | W36: =V36*(1+W37) -> -342.53413 | X36: =W36*(1+X37) -> -393.91425
A37: % growth | C37: =C36/B36-1 -> 0.099843994 | D37: =D36/C36-1 -> -0.76595745 | E37: =E36/D36-1 -> 0.10909091 | F37: =F36/E36-1 -> 0.19125683 | G37: =G36/F36-1 -> 0.13302752 | H37: =H36/C36-1 -> 0.15319149 | I37: =I36/H36-1 -> -0.70725707 | J37: =J36/I36-1 -> -0.037815126 | K37: =K36/J36-1 -> 0.026200873 | L37: =L36/K36-1 -> -0.05106383 | M37: =M36/H36-1 -> 0.13776138 | N37: =N36/M36-1 -> -0.72 | O37: =O36/N36-1 -> 0.35521236 | P37: =P36/O36-1 -> 0.29344729 | Q37: =Q36/P36-1 -> 0.40748899 | R37: =R36/M36-1 -> 0.84108108 | S37: 0.15 | T37: 0.15 | U37: 0.15 | V37: 0.15 | W37: 0.15 | X37: 0.15
A38: Interest expense, net | B38: =B33+B34+B35+B36 -> 78.6 | C38: =C33+C34+C35+C36 -> 302 | D38: =D33+D34+D35+D36 -> -8.4 | E38: =E33+E34+E35+E36 -> #VALUE! | F38: =F33+F34+F35+F36 -> 51.1 | G38: =G33+G34+G35+G36 -> -12.2 | H38: =H33+H34+H35+H36 -> 26.7 | I38: =I33+I34+I35+I36 -> #VALUE! | ... X38: =X33+X34+X35+X36 -> -202.51425
A40: Pretax income | B40: =B30+B38 -> 3159.7 | C40: =C30+C38 -> 3903 | D40: =D30+D38 -> 1049.6 | E40: =E30+E38 -> #VALUE! | F40: =F30+F38 -> 1073.4 | G40: =G30+G38 -> 1215.2 | H40: =H30+H38 -> 4198.6 | I40: =I30+I38 -> #VALUE! | ... X40: =X30+X38 -> 6666.011
A42: Provision for income taxes | B42: 1092 | C42: 1143.7 | D42: 361.9 | E42: 285.4 | F42: 318.9 | G42: =H42-SUM(D42:F42) -> 413.5 | H42: 1379.7 | I42: 381.4 | J42: 327.6 | K42: 361.1 | L42: =M42-SUM(I42:K42) -> 362.5 | M42: 1432.6 | N42: 755.8 | O42: 155.8 | P42: 174.8 | Q42: =R42-SUM(N42:P42) -> 175.6 | R42: 1262 | S42: =S43*S40 -> 999.13341 | T42: =T43*T40 -> 1011.1144 | U42: =U43*U40 -> 1093.9362 | V42: =V43*V40 -> 1175.8179 | W42: =W43*W40 -> 1254.0116 | X42: =X43*X40 -> 1333.2022
A43: Effective tax rate | B43: =B42/B40 -> 0.34560243 | C43: =C42/C40 -> 0.293031 | D43: =D42/D40 -> 0.34479802 | E43: =E42/E40 -> #VALUE! | F43: =F42/F40 -> 0.29709335 | G43: =G42/G40 -> 0.34027321 | H43: =H42/H40 -> 0.32860954 | I43: =I42/I40 -> #VALUE! | ... R43: =R42/R40 -> 0.2183391 | S43: 0.2 | T43: 0.2 | U43: 0.2 | V43: 0.2 | W43: 0.2 | X43: 0.2
A45: Net income | B45: =B40-B42 -> 2067.7 | C45: =C40-C42 -> 2759.3 | D45: =D40-D42 -> 687.7 | E45: =E40-E42 -> #VALUE! | F45: =F40-F42 -> 754.5 | G45: =G40-G42 -> 801.7 | H45: =H40-H42 -> 2818.9 | I45: =I40-I42 -> #VALUE! | ... X45: =X40-X42 -> 5332.8088
A46: Net income margin | B46: =B45/B9 -> 0.12571286 | C46: =C45/C9 -> 0.14399328 | D46: =D45/D9 -> 0.1279799 | E46: =E45/E9 -> #VALUE! | F46: =F45/F9 -> 0.14404353 | G46: =G45/G9 -> 0.1403733 | H46: =H45/H9 -> 0.13224401 | I46: =I45/I9 -> #VALUE! | ... X46: =X45/X9 -> 0.13507115
A48: EBITDA | B48: =B30+B22 -> 3790.7 | C48: =C30+C22 -> 4494.9 | D48: =D30+D22 -> 1293.5 | E48: =E30+E22 -> 1112 | F48: =F30+F22 -> 1269.9 | G48: =G30+G22 -> 1477.3 | H48: =H30+H22 -> 5152.7 | I48: =I30+I22 -> #VALUE! | ... X48: =X30+X22 -> 9337.1713
A49: EBITDA margin | B49: =B48/B9 -> 0.23046851 | C49: =C48/C9 -> 0.23456507 | D49: =D48/D9 -> 0.24071834 | E49: =E48/E9 -> 0.22270288 | F49: =F48/F9 -> 0.24243986 | G49: =G48/G9 -> 0.25866718 | H49: =H48/H9 -> 0.24173035 | I49: =I48/I9 -> #VALUE! | ... X49: =X48/X9 -> 0.23649498

Sheet Balance Sheet
A1: Fiscal Year | B1: 2014A | C1: 2015A | D1: 2016A | E1: 2017A | F1: 2018A | G1: 2019E | H1: 2020E | I1: 2021E | J1: 2022E | K1: 2023E | L1: 2024E | N1: Q1 2019 | O1: Q2 2019 | P1: Q3 2019
A2: ASSETS
A3: Current assets:
A4: Cash and cash equivalents | B4: 1708.4 | C4: 1530.1 | D4: 2128.8 | E4: 2462.3 | F4: 8756.3 | G4: ='Cash Flows'!G37 -> 10183.689 | H4: ='Cash Flows'!H37 -> 11936.664 | I4: ='Cash Flows'!I37 -> 14063.462 | J4: ='Cash Flows'!J37 -> 16490.764 | K4: ='Cash Flows'!K37 -> 19312.152 | L4: ='Cash Flows'!L37 -> 22527.668 | N4: 4761.6 | O4: 2055.1 | P4: 4763.3
A5: Short-term investments | B5: 135.4 | C5: 81.3 | D5: 134.4 | E5: 228.6 | F5: 181.5 | G5: =(G6+1)*F5 -> 185.13 | H5: =(H6+1)*G5 -> 188.8326 | I5: =(I6+1)*H5 -> 192.60925 | J5: =(J6+1)*I5 -> 196.46144 | K5: =(K6+1)*J5 -> 200.39067 | L5: =(L6+1)*K5 -> 204.39848 | N5: 230.2 | O5: 76.6 | P5: 72.1
A6: % growth | C6: =C5/B5-1 -> -0.39955687 | D6: =D5/C5-1 -> 0.65313653 | E6: =E5/D5-1 -> 0.70089286 | F6: =F5/E5-1 -> -0.20603675 | G6: 0.02 | H6: 0.02 | I6: 0.02 | J6: 0.02 | K6: 0.02 | L6: 0.02
A8: Accounts receivable, net | B8: 631 | C8: 719 | D8: 768.8 | E8: 870.4 | F8: 693.1 | G8: ='Income Statement'!S9/(365/'Balance Sheet'!G9) -> 929.61666 | H8: ='Income Statement'!T9/(365/'Balance Sheet'!H9) -> 1025.159 | I8: ='Income Statement'!U9/(365/'Balance Sheet'!I9) -> 1108.6379 | J8: ='Income Statement'!V9/(365/'Balance Sheet'!J9) -> 1196.3182 | K8: ='Income Statement'!W9/(365/'Balance Sheet'!K9) -> 1287.7309 | L8: ='Income Statement'!X9/(365/'Balance Sheet'!L9) -> 1298.0212 | N8: 721.4 | O8: 703.6 | P8: 790.6
A9: Days receivable outstanding | C9: =365/('Income Statement'!C9/AVERAGE(B8,C8)) -> 12.857009 | D9: =365/('Income Statement'!H9/AVERAGE(C8,D8)) -> 12.738073 | E9: =365/('Income Statement'!M9/AVERAGE(D8,E8)) -> 13.362964 | F9: =365/('Income Statement'!R9/AVERAGE(E8,F8)) -> 11.543063 | G9: 12.8 | H9: 12.8 | I9: 12.8 | J9: 12.8 | K9: 12.8 | L9: 12
A11: Inventories | B11: 1090.9 | C11: 1306.4 | D11: 1378.5 | E11: 1364 | F11: 1400.5 | G11: ='Income Statement'!S12/'Balance Sheet'!G12 -> 1496.8356 | H11: ='Income Statement'!T12/'Balance Sheet'!H12 -> 1578.5905 | I11: ='Income Statement'!U12/'Balance Sheet'!I12 -> 1668.4512 | J11: ='Income Statement'!V12/'Balance Sheet'!J12 -> 1803.6474 | K11: ='Income Statement'!W12/'Balance Sheet'!K12 -> 1886.5783 | L11: ='Income Statement'!X12/'Balance Sheet'!L12 -> 2010.2103 | N11: 1354.6 | O11: 1443 | P11: 1517.2
A12: Inventory turnover | B12: ='Income Statement'!B12/AVERAGE('Balance Sheet'!B11) -> 6.2872857 | C12: ='Income Statement'!C12/AVERAGE('Balance Sheet'!C11,B11) -> 6.4968923 | D12: ='Income Statement'!H12/AVERAGE('Balance Sheet'!D11,C11) -> 6.3399754 | E12: ='Income Statement'!M12/AVERAGE('Balance Sheet'!E11,D11) -> 6.5883683 | F12: ='Income Statement'!R12/AVERAGE('Balance Sheet'!F11,E11) -> 7.3608247 | G12: =365/G13 -> 7.3 | H12: =365/H13 -> 7.4338086 | I12: =365/I13 -> 7.5257732 | J12: =365/J13 -> 7.4489796 | K12: =365/K13 -> 7.6200418 | L12: =365/L13 -> 7.6519916
A13: Days inventory outstanding | B13: =365/B12 -> 58.053668 | C13: =365/C12 -> 56.180706 | D13: =365/D12 -> 57.571201 | E13: =365/E12 -> 55.400667 | F13: =365/F12 -> 49.586835 | G13: 50 | H13: 49.1 | I13: 48.5 | J13: 49 | K13: 47.9 | L13: 47.7
A15: Prepaid expenses and other current assets | B15: 285.6 | C15: 334.2 | D15: 350 | E15: 358.1 | F15: 1462.8 | G15: ='Income Statement'!S9*'Balance Sheet'!G16 -> 1590.516 | H15: ='Income Statement'!T9*'Balance Sheet'!H16 -> 1753.9829 | I15: ='Income Statement'!U9*'Balance Sheet'!I16 -> 1896.8102 | J15: ='Income Statement'!V9*'Balance Sheet'!J16 -> 2046.8257 | K15: ='Income Statement'!W9*'Balance Sheet'!K16 -> 2203.2271 | L15: ='Income Statement'!X9*'Balance Sheet'!L16 -> 2368.8887 | N15: 608.5 | O15: 674 | P15: 591.6
A16: % of revenue | B16: =B15/'Income Statement'!B9 -> 0.017364024 | C16: =C15/'Income Statement'!C9 -> 0.017440131 | D16: =D15/'Income Statement'!H9 -> 0.016419668 | E16: =E15/'Income Statement'!M9 -> 0.015996033 | F16: =F15/'Income Statement'!R9 -> 0.059175954 | G16: 0.06 | H16: 0.06 | I16: 0.06 | J16: 0.06 | K16: 0.06 | L16: 0.06
A18: Total current assets | B18: =B4+B5+B8+B11++B15+B17 -> 3851.3 | C18: =C4+C5+C8+C11++C15+C17 -> 3971 | D18: =D4+D5+D8+D11++D15+D17 -> 4760.5 | E18: =E4+E5+E8+E11++E15+E17 -> 5283.4 | F18: =F4+F5+F8+F11++F15+F17 -> 12494.2 | G18: =G4+G5+G8+G11++G15+G17 -> 14385.787 | H18: =H4+H5+H8+H11++H15+H17 -> 16483.229 | I18: =I4+I5+I8+I11++I15+I17 -> 18929.971 | ... L18: =L4+L5+L8+L11++L15+L17 -> 28409.187 | N18: =SUM(N4:N17) -> 7676.3 | O18: =SUM(O4:O17) -> 4952.3 | P18: =SUM(P4:P17) -> 7734.8
A19: Long-term investments | B19: 318.4 | C19: 312.5 | D19: 1141.7 | E19: 542.3 | F19: 267.7 | G19: 267.7 | H19: 267.7 | I19: 267.7 | J19: 267.7 | K19: 267.7 | L19: 267.7 | N19: 265 | O19: 251.9 | P19: 222.6
A20: Equity and cost investments | B20: 514.9 | C20: 352 | D20: 354.5 | E20: 481.6 | F20: 334.7 | G20: 334.7 | H20: 334.7 | I20: 334.7 | J20: 334.7 | K20: 334.7 | L20: 334.7 | N20: 336.1 | O20: 309.3 | P20: 340.3
A22: Property at cost:
A23: Gross PP&E | B23: 8581.1 | C23: 9641.8 | D23: 10573.3 | E23: 11584 | F23: 13197.1 | G23: =F23+G24 -> 15105.719 | H23: =G23+H24 -> 17210.499 | I23: =H23+I24 -> 19486.671 | J23: =I23+J24 -> 21942.862 | K23: =J23+K24 -> 24586.734 | L23: =K23+L24 -> 27429.401 | N23: 6039.3 | O23: 6135.5 | P23: 6187.8
A24: Capex | B24: =-'Cash Flows'!B26 -> 1160.9 | C24: =-'Cash Flows'!C26 -> 1303.7 | D24: =-'Cash Flows'!D26 -> 1440.3 | E24: =-'Cash Flows'!E26 -> 1519.4 | F24: =-'Cash Flows'!F26 -> 1976.4 | G24: ='Income Statement'!S9*'Balance Sheet'!G25 -> 1908.6192 | H24: ='Income Statement'!T9*'Balance Sheet'!H25 -> 2104.7795 | I24: ='Income Statement'!U9*'Balance Sheet'!I25 -> 2276.1723 | J24: ='Income Statement'!V9*'Balance Sheet'!J25 -> 2456.1909 | K24: ='Income Statement'!W9*'Balance Sheet'!K25 -> 2643.8726 | L24: ='Income Statement'!X9*'Balance Sheet'!L25 -> 2842.6664
A25: % of revenue | B25: =B24/'Income Statement'!B9 -> 0.070580868 | C25: =C24/'Income Statement'!C9 -> 0.06803321 | D25: =D24/'Income Statement'!H9 -> 0.067569279 | E25: =E24/'Income Statement'!M9 -> 0.067870352 | F25: =F24/'Income Statement'!R9 -> 0.079953073 | G25: 0.072 | H25: 0.072 | I25: 0.072 | J25: 0.072 | K25: 0.072 | L25: 0.072
A26: Depreciation | B26: ='Income Statement'!B22 -> 709.6 | C26: ='Income Statement'!C22 -> 893.9 | D26: ='Income Statement'!H22 -> 980.8 | E26: ='Income Statement'!M22 -> 1011.4 | F26: ='Income Statement'!R22 -> 1247 | G26: =G23*G27 -> 1359.5147 | H26: =H23*H27 -> 1548.9449 | I26: =I23*I27 -> 1753.8004 | J26: =J23*J27 -> 1974.8576 | K26: =K23*K27 -> 2212.8061 | L26: =L23*L27 -> 2468.6461
A27: % of gross PP&E | B27: =B26/B23 -> 0.082693361 | C27: =C26/C23 -> 0.092710905 | D27: =D26/D23 -> 0.092761957 | E27: =E26/E23 -> 0.087310083 | F27: =F26/F23 -> 0.094490456 | G27: 0.09 | H27: 0.09 | I27: 0.09 | J27: 0.09 | K27: 0.09 | L27: 0.09
A28: Less accumulated depreciation and amortization | B28: 5062.1 | C28: 5553.5 | D28: 6039.5 | E28: 6664.5 | F28: 7268 | G28: =F28+G26 -> 8627.5147 | H28: =G28+H26 -> 10176.46 | I28: =H28+I26 -> 11930.26 | J28: =I28+J26 -> 13905.118 | K28: =J28+K26 -> 16117.924 | L28: =K28+L26 -> 18586.57
A29: Net property at cost | B29: =B23-B28 -> 3519 | C29: =C23-C28 -> 4088.3 | D29: =D23-D28 -> 4533.8 | E29: =E23-E28 -> 4919.5 | F29: =F23-F28 -> 5929.1 | G29: =G23-G28 -> 6478.2045 | H29: =H23-H28 -> 7034.0391 | I29: =I23-I28 -> 7556.411 | ... L29: =L23-L28 -> 8842.8311
N30: 650 | O30: 1006.6 | P30: 1533
A31: Deferred income taxes, net | B31: =903.3+317.4 -> 1220.7 | C31: 1180.8 | D31: 885.4 | E31: 795.4 | F31: 134.7 | G31: =F31*1.02 -> 137.394 | H31: =G31*1.02 -> 140.14188 | I31: =H31*1.02 -> 142.94472 | J31: =I31*1.02 -> 145.80361 | K31: =J31*1.02 -> 148.71968 | L31: =K31*1.02 -> 151.69408 | N31: 472.7 | O31: 464.5 | P31: 458
A32: Other long-term assets | B32: 198.9 | C32: 415.9 | D32: 417.7 | E32: 362.8 | F32: 412.2 | G32: =F32*1.01 -> 416.322 | H32: =G32*1.01 -> 420.48522 | I32: =H32*1.01 -> 424.69007 | J32: =I32*1.01 -> 428.93697 | K32: =J32*1.01 -> 433.22634 | L32: =K32*1.01 -> 437.55861 | N32: 981.6 | O32: 918.3 | P32: 853.2
A33: Other intangible assets | B33: 273.5 | C33: 520.4 | D33: 516.3 | E33: 441.4 | F33: 1042.2 | G33: =F33 -> 1042.2 | H33: =G33 -> 1042.2 | I33: =H33 -> 1042.2 | J33: =I33 -> 1042.2 | K33: =J33 -> 1042.2 | L33: =K33 -> 1042.2 | N33: 3560.3 | O33: 3603.5 | P33: 3564.7
A34: Goodwill | B34: 856.2 | C34: 1575.4 | D34: 1719.6 | E34: 1539.2 | F34: 3541.6 | G34: 3541.6 | H34: 3541.6 | I34: 3541.6 | J34: 3541.6 | K34: 3541.6 | L34: 3541.6 | N34: =SUM(N18:N33) -> 19981.3 | O34: =SUM(O18:O33) -> 17641.9 | P34: =SUM(P18:P33) -> 20894.4
A35: TOTAL ASSETS | B35: =B18+B19+B20+B29+B31+B32+B33+B34 -> 10752.9 | C35: =C18+C19+C20+C29+C31+C32+C33+C34 -> 12416.3 | D35: =D18+D19+D20+D29+D31+D32+D33+D34 -> 14329.5 | E35: =E18+E19+E20+E29+E31+E32+E33+E34 -> 14365.6 | F35: =F18+F19+F20+F29+F31+F32+F33+F34 -> 24156.4 | G35: =G18+G19+G20+G29+G31+G32+G33+G34 -> 26603.907 | H35: =H18+H19+H20+H29+H31+H32+H33+H34 -> 29264.095 | I35: =I18+I19+I20+I29+I31+I32+I33+I34 -> 32240.216 | ... L35: =L18+L19+L20+L29+L31+L32+L33+L34 -> 43027.471
A37: LIABILITIES AND EQUITY
A38: Current liabilities: | N38: 1100.5 | O38: 1096.7 | P38: 1145.4
A39: Accounts payable | B39: 533.7 | C39: 684.2 | D39: 730.6 | E39: 782.5 | F39: 1179.3 | G39: ='Income Statement'!S12/(365/'Balance Sheet'!G40) -> 1077.7216 | H39: ='Income Statement'!T12/(365/'Balance Sheet'!H40) -> 1157.4187 | I39: ='Income Statement'!U12/(365/'Balance Sheet'!I40) -> 1238.438 | J39: ='Income Statement'!V12/(365/'Balance Sheet'!J40) -> 1325.1287 | K39: ='Income Statement'!W12/(365/'Balance Sheet'!K40) -> 1417.8877 | L39: ='Income Statement'!X12/(365/'Balance Sheet'!L40) -> 1517.1398
A40: Days outstanding | C40: =365/('Income Statement'!C12/AVERAGE(B39,C39)) -> 28.541477 | D40: =365/('Income Statement'!H12/AVERAGE(C39,D39)) -> 30.336972 | E40: =365/('Income Statement'!M12/AVERAGE(D39,E39)) -> 30.565816 | F40: =365/('Income Statement'!R12/AVERAGE(E39,F39)) -> 35.188805 | G40: 36 | H40: 36 | I40: 36 | J40: 36 | K40: 36 | L40: 36
N41: 2564 | O41: 2569.3 | P41: 3238.7
A42: Accrued liabilities | B42: 1514.4 | C42: 1755.3 | D42: 1999.1 | E42: 1934.5 | F42: 2298.4 | G42: =F42*(1+G43) -> 2332.876 | H42: =G42*(1+H43) -> 2367.8691 | I42: =H42*(1+I43) -> 2403.3872 | J42: =I42*(1+J43) -> 2439.438 | K42: =J42*(1+K43) -> 2476.0296 | L42: =K42*(1+L43) -> 2513.17
A43: % growth | C43: =C42/B42-1 -> 0.1590729 | D43: =D42/C42-1 -> 0.13889364 | E43: =E42/D42-1 -> -0.032314542 | F43: =F42/E42-1 -> 0.18811062 | G43: 0.015 | H43: 0.015 | I43: 0.015 | J43: 0.015 | K43: 0.015 | L43: 0.015 | N43: 208.8 | O43: 221 | P43: 211.5
A44: Insurance reserves | B44: 196.1 | C44: 224.8 | D44: 246 | E44: 215.2 | F44: 213.7 | G44: 213.7 | H44: 213.7 | I44: 213.7 | J44: 213.7 | K44: 213.7 | L44: 213.7
N45: 1554.2 | O45: 1311.4 | P45: 1300.2
A46: Stored value card liability and current portion of deferred revenue | B46: 794.5 | C46: 983.8 | D46: 1171.2 | E46: 1288.5 | F46: 1642.9 | G46: 1642.9 | H46: 1642.9 | I46: 1642.9 | J46: 1642.9 | K46: 1642.9 | L46: 1642.9
...

Sheet Cash Flows
A1: Fiscal Year Ended | B1: 2014 | C1: 2015 | D1: 2016 | E1: 2017 | F1: 2018A | G1: 2019E | H1: 2020E | I1: 2021E | J1: 2022E | K1: 2023E | L1: 2024E
A2: OPERATING ACTIVITIES:
A3: Net earnings including noncontrolling interests | B3: ='Income Statement'!B45 -> 2067.7 | C3: ='Income Statement'!C45 -> 2759.3 | D3: ='Income Statement'!H45 -> 2818.9 | E3: ='Income Statement'!M45 -> 2884.9 | F3: ='Income Statement'!R45 -> 4518 | G3: ='Income Statement'!S45 -> 3996.5337 | H3: ='Income Statement'!T45 -> 4044.4576 | I3: ='Income Statement'!U45 -> 4375.745 | J3: ='Income Statement'!V45 -> 4703.2715 | K3: ='Income Statement'!W45 -> 5016.0462 | L3: ='Income Statement'!X45 -> 5332.8088
A4: Adjustments to reconcile net earnings to net cash provided by operating activities:
A5: Depreciation and amortization | B5: 748.4 | C5: 933.8 | D5: 1030.1 | E5: 1067.1 | F5: 1305.9 | G5: ='Balance Sheet'!G26 -> 1359.5147 | H5: ='Balance Sheet'!H26 -> 1548.9449 | I5: ='Balance Sheet'!I26 -> 1753.8004 | J5: ='Balance Sheet'!J26 -> 1974.8576 | K5: ='Balance Sheet'!K26 -> 2212.8061 | L5: ='Balance Sheet'!L26 -> 2468.6461
A6: Income earned from equity method investees | B6: -182.7 | C6: -190.2 | D6: -250.2 | E6: -310.2 | F6: -242.8 | G6: 0 | H6: 0 | I6: 0 | J6: 0 | K6: 0 | L6: 0
A7: Interest income | F7: =-'Income Statement'!R35 -> -191.4 | G7: 0 | H7: 0 | I7: 0 | J7: 0 | K7: 0 | L7: 0
A8: Gain resulting from acquisition of joint venture | B8: -70.2 | C8: -394.3 | D8: 0 | E8: 0 | F8: -1376.4 | G8: ='Income Statement'!S33 -> 0 | H8: ='Income Statement'!T33 -> 0 | I8: ='Income Statement'!U33 -> 0 | J8: ='Income Statement'!V33 -> 0 | K8: ='Income Statement'!W33 -> 0 | L8: ='Income Statement'!X33 -> 0
A9: Net gain resulting from divestiture of certain retail operations | B9: 0 | C9: 0 | D9: -6.1 | E9: -93.5 | F9: =-'Income Statement'!R34 -> -499.2 | G9: 0 | H9: =-'Income Statement'!T34 -> 0 | I9: =-'Income Statement'!U34 -> 0 | J9: =-'Income Statement'!V34 -> 0 | K9: =-'Income Statement'!W34 -> 0 | L9: =-'Income Statement'!X34 -> 0
A10: Stock-based compensation | B10: 183.2 | C10: 209.8 | D10: 218.1 | E10: 176 | F10: 250.3 | G10: ='Balance Sheet'!G60 -> 250.3 | H10: ='Balance Sheet'!H60 -> 250.3 | I10: ='Balance Sheet'!I60 -> 250.3 | J10: ='Balance Sheet'!J60 -> 250.3 | K10: ='Balance Sheet'!K60 -> 250.3 | L10: ='Balance Sheet'!L60 -> 250.3
A11: Short term investments | F11: =-'Balance Sheet'!F5+'Balance Sheet'!E5 -> 47.1 | G11: =-'Balance Sheet'!G5+'Balance Sheet'!F5 -> -3.63 | H11: =-'Balance Sheet'!H5+'Balance Sheet'!G5 -> -3.7026 | I11: =-'Balance Sheet'!I5+'Balance Sheet'!H5 -> -3.776652 | J11: =-'Balance Sheet'!J5+'Balance Sheet'!I5 -> -3.852185 | K11: =-'Balance Sheet'!K5+'Balance Sheet'!J5 -> -3.9292287 | L11: =-'Balance Sheet'!L5+'Balance Sheet'!K5 -> -4.0078133
A12: Deferred income taxes, net | B12: 10.2 | C12: 21.2 | D12: 265.7 | E12: 95.1 | F12: =-'Balance Sheet'!F31+'Balance Sheet'!E31 -> 660.7 | G12: =-'Balance Sheet'!G31+'Balance Sheet'!F31 -> -2.694 | H12: =-'Balance Sheet'!H31+'Balance Sheet'!G31 -> -2.74788 | I12: =-'Balance Sheet'!I31+'Balance Sheet'!H31 -> -2.8028376 | J12: =-'Balance Sheet'!J31+'Balance Sheet'!I31 -> -2.8588944 | K12: =-'Balance Sheet'!K31+'Balance Sheet'!J31 -> -2.9160722 | L12: =-'Balance Sheet'!L31+'Balance Sheet'!K31 -> -2.9743937
A13: Other long term assets | F13: =-'Balance Sheet'!F32+'Balance Sheet'!E32 -> -49.4 | G13: =-'Balance Sheet'!G32+'Balance Sheet'!F32 -> -4.122 | H13: =-'Balance Sheet'!H32+'Balance Sheet'!G32 -> -4.16322 | I13: =-'Balance Sheet'!I32+'Balance Sheet'!H32 -> -4.2048522 | J13: =-'Balance Sheet'!J32+'Balance Sheet'!I32 -> -4.2469007 | K13: =-'Balance Sheet'!K32+'Balance Sheet'!J32 -> -4.2893697 | L13: =-'Balance Sheet'!L32+'Balance Sheet'!K32 -> -4.3322634
A14: Other long term liabilities | F14: ='Balance Sheet'!F53-'Balance Sheet'!E53 -> 679.6 | G14: ='Balance Sheet'!G53-'Balance Sheet'!F53 -> 28.61 | H14: ='Balance Sheet'!H53-'Balance Sheet'!G53 -> 29.1822 | I14: ='Balance Sheet'!I53-'Balance Sheet'!H53 -> 29.765844 | J14: ='Balance Sheet'!J53-'Balance Sheet'!I53 -> 30.361161 | K14: ='Balance Sheet'!K53-'Balance Sheet'!J53 -> 30.968384 | L14: ='Balance Sheet'!L53-'Balance Sheet'!K53 -> 31.587752
A15: Current portion of long term liabilities | F15: ='Balance Sheet'!F49-'Balance Sheet'!E49 -> 349.9 | G15: ='Balance Sheet'!G49-'Balance Sheet'!F49 -> 0 | H15: ='Balance Sheet'!H49-'Balance Sheet'!G49 -> 0 | I15: ='Balance Sheet'!I49-'Balance Sheet'!H49 -> 0 | J15: ='Balance Sheet'!J49-'Balance Sheet'!I49 -> 0 | K15: ='Balance Sheet'!K49-'Balance Sheet'!J49 -> 0 | L15: ='Balance Sheet'!L49-'Balance Sheet'!K49 -> 0
A16: Cash provided by changes in operating assets and liabilities:
A17: Accounts receivable | B17: -79.7 | C17: -82.8 | D17: -55.6 | E17: -96.8 | F17: 131 | G17: =-('Balance Sheet'!G8-'Balance Sheet'!F8) -> -236.51666 | H17: =-('Balance Sheet'!H8-'Balance Sheet'!G8) -> -95.542317 | I17: =-('Balance Sheet'!I8-'Balance Sheet'!H8) -> -83.478971 | J17: =-('Balance Sheet'!J8-'Balance Sheet'!I8) -> -87.680297 | K17: =-('Balance Sheet'!K8-'Balance Sheet'!J8) -> -91.412685 | L17: =-('Balance Sheet'!L8-'Balance Sheet'!K8) -> -10.290274
A18: Inventories | B18: 14.3 | C18: -207.9 | D18: -67.5 | E18: 14 | F18: -41.2 | G18: =-('Balance Sheet'!G11-'Balance Sheet'!F11) -> -96.335616 | H18: =-('Balance Sheet'!H11-'Balance Sheet'!G11) -> -81.754897 | I18: =-('Balance Sheet'!I11-'Balance Sheet'!H11) -> -89.860702 | J18: =-('Balance Sheet'!J11-'Balance Sheet'!I11) -> -135.19615 | K18: =-('Balance Sheet'!K11-'Balance Sheet'!J11) -> -82.93097 | L18: =-('Balance Sheet'!L11-'Balance Sheet'!K11) -> -123.63193
A19: Prepaid expenses and other current assets | B19: 4.6 | C19: 49.5 | D19: 0 | E19: 0 | F19: =-'Balance Sheet'!F15+'Balance Sheet'!E15 -> -1104.7 | G19: =-'Balance Sheet'!G15+'Balance Sheet'!F15 -> -127.716 | H19: =-'Balance Sheet'!H15+'Balance Sheet'!G15 -> -163.46693 | I19: =-'Balance Sheet'!I15+'Balance Sheet'!H15 -> -142.8273 | J19: =-'Balance Sheet'!J15+'Balance Sheet'!I15 -> -150.01551 | K19: =-'Balance Sheet'!K15+'Balance Sheet'!J15 -> -156.40139 | L19: =-'Balance Sheet'!L15+'Balance Sheet'!K15 -> -165.66156
A20: Accounts payable | B20: 60.4 | C20: 137.7 | D20: 46.9 | E20: 46.4 | F20: =('Balance Sheet'!F39-'Balance Sheet'!E39) -> 396.8 | G20: =('Balance Sheet'!G39-'Balance Sheet'!F39) -> -101.57836 | H20: =('Balance Sheet'!H39-'Balance Sheet'!G39) -> 79.697063 | I20: =('Balance Sheet'!I39-'Balance Sheet'!H39) -> 81.019309 | J20: =('Balance Sheet'!J39-'Balance Sheet'!I39) -> 86.690661 | K20: =('Balance Sheet'!K39-'Balance Sheet'!J39) -> 92.759007 | L20: =('Balance Sheet'!L39-'Balance Sheet'!K39) -> 99.252138
A21: Accrued liabilities and insurance reserves | B21: 103.9 | C21: 124.4 | D21: 0 | E21: 0 | F21: ='Balance Sheet'!F42-'Balance Sheet'!E42+'Balance Sheet'!F44-'Balance Sheet'!E44 -> 362.4 | G21: ='Balance Sheet'!G42-'Balance Sheet'!F42+'Balance Sheet'!G44-'Balance Sheet'!F44 -> 34.476 | H21: ='Balance Sheet'!H42-'Balance Sheet'!G42+'Balance Sheet'!H44-'Balance Sheet'!G44 -> 34.99314 | I21: ='Balance Sheet'!I42-'Balance Sheet'!H42+'Balance Sheet'!I44-'Balance Sheet'!H44 -> 35.518037 | J21: ='Balance Sheet'!J42-'Balance Sheet'!I42+'Balance Sheet'!J44-'Balance Sheet'!I44 -> 36.050808 | K21: ='Balance Sheet'!K42-'Balance Sheet'!J42+'Balance Sheet'!K44-'Balance Sheet'!J44 -> 36.59157 | L21: ='Balance Sheet'!L42-'Balance Sheet'!K42+'Balance Sheet'!L44-'Balance Sheet'!K44 -> 37.140443
A22: Net cash provided by operating activities | B22: =SUM(B3:B21) -> 2860.1 | C22: =SUM(C3:C21) -> 3360.5 | D22: =SUM(D3:D21) -> 4000.3 | E22: =SUM(E3:E21) -> 3783 | F22: =F3+SUM(F5:F15)+SUM(F17:F21) -> 5196.6 | G22: =G3+SUM(G5:G15)+SUM(G17:G21) -> 5096.8418 | H22: =H3+SUM(H5:H14)+SUM(H17:H21) -> 5636.1971 | I22: =I3+SUM(I5:I14)+SUM(I17:I21) -> 6199.1973 | J22: =J3+SUM(J5:J14)+SUM(J17:J21) -> 6697.6817 | K22: =K3+SUM(K5:K14)+SUM(K17:K21) -> 7297.5916 | L22: =L3+SUM(L5:L14)+SUM(L17:L21) -> 7908.837
A24: INVESTING ACTIVITIES:
A25: Purchases of investments | B25: -1652.5 | C25: -567.4 | D25: -1585.7 | E25: -674.4 | F25: -191.9 | G25: 0 | H25: 0 | I25: 0 | J25: 0 | K25: 0 | L25: 0
A26: Capital expenditure (additions to property, plant and equipment) | B26: -1160.9 | C26: -1303.7 | D26: -1440.3 | E26: -1519.4 | F26: -1976.4 | G26: =-'Balance Sheet'!G24 -> -1908.6192 | H26: =-'Balance Sheet'!H24 -> -2104.7795 | I26: =-'Balance Sheet'!I24 -> -2276.1723 | J26: =-'Balance Sheet'!J24 -> -2456.1909 | K26: =-'Balance Sheet'!K24 -> -2643.8726 | L26: =-'Balance Sheet'!L24 -> -2842.6664
A27: Net cash used by investing activities | B27: =SUM(B25:B26) -> -2813.4 | C27: =SUM(C25:C26) -> -1871.1 | D27: =SUM(D25:D26) -> -3026 | E27: =SUM(E25:E26) -> -2193.8 | F27: =SUM(F25:F26) -> -2168.3 | G27: =SUM(G25:G26) -> -1908.6192 | H27: =SUM(H25:H26) -> -2104.7795 | I27: =SUM(I25:I26) -> -2276.1723 | ... L27: =SUM(L25:L26) -> -2842.6664
A29: FINANCING ACTIVITIES:
A30: Cash dividends paid | B30: ='Balance Sheet'!B61 -> -783.1 | C30: ='Balance Sheet'!C61 -> -928.6 | D30: ='Balance Sheet'!D61 -> -1178 | E30: ='Balance Sheet'!E61 -> -1450.4 | F30: ='Balance Sheet'!F61 -> -1743.4 | G30: ='Balance Sheet'!G61 -> -1760.834 | H30: ='Balance Sheet'!H61 -> -1778.4423 | I30: ='Balance Sheet'!I61 -> -1796.2268 | ... L30: ='Balance Sheet'!L61 -> -1850.6542
A31: Net cash used by financing activities | B31: =SUM(B30:B30) -> -783.1 | C31: =SUM(C30:C30) -> -928.6 | D31: =SUM(D30:D30) -> -1178 | E31: =SUM(E30:E30) -> -1450.4 | F31: =SUM(F30:F30) -> -1743.4 | G31: =G30 -> -1760.834 | H31: =H30 -> -1778.4423 | I31: =I30 -> -1796.2268 | J31: =J30 -> -1814.189 | K31: =K30 -> -1832.3309 | L31: =L30 -> -1850.6542
A33: Net (decrease)/increase in cash and cash equivalents | B33: =B22+B27+B31+#REF! -> #REF! | C33: =C22+C27+C31+#REF! -> #REF! | D33: =D22+D27+D31+#REF! -> #REF! | E33: =E22+E27+E31 -> 138.8 | F33: =F22+F27+F31 -> 1284.9 | G33: =G22+G27+G31 -> 1427.3886 | H33: =H22+H27+H31 -> 1752.9752 | I33: =I22+I27+I31 -> 2126.7982 | J33: =J22+J27+J31 -> 2427.3018 | K33: =K22+K27+K31 -> 2821.3881 | L33: =L22+L27+L31 -> 3215.5163
A35: CASH AND CASH EQUIVALENTS:
A36: Beginning of period | B36: 2575.7 | C36: ='Balance Sheet'!B4 -> 1708.4 | D36: ='Balance Sheet'!C4 -> 1530.1 | E36: ='Balance Sheet'!D4 -> 2128.8 | F36: ='Balance Sheet'!E4 -> 2462.3 | G36: =F37 -> 8756.3 | H36: =G37 -> 10183.689 | I36: =H37 -> 11936.664 | J36: =I37 -> 14063.462 | K36: =J37 -> 16490.764 | L36: =K37 -> 19312.152
A37: End of period | B37: ='Balance Sheet'!B4 -> 1708.4 | C37: ='Balance Sheet'!C4 -> 1530.1 | D37: ='Balance Sheet'!D4 -> 2128.8 | E37: ='Balance Sheet'!E4 -> 2462.3 | F37: 8756.3 | G37: =G36+G33 -> 10183.689 | H37: =H36+H33 -> 11936.664 | I37: =I36+I33 -> 14063.462 | J37: =J36+J33 -> 16490.764 | K37: =K36+K33 -> 19312.152 | L37: =L36+L33 -> 22527.668
A39: SUPPLEMENTAL DISCLOSURE OF CASH FLOW INFORMATION:
A40: Cash paid during the period for:
A41: Interest, net of capitalized interest | B41: 56.2 | C41: 69.5 | D41: 74.7 | E41: 96.6 | F41: 137.1 | G41: 0 | H41: 0 | I41: 0 | J41: 0 | K41: 0 | L41: 0
A42: Income taxes, net of refunds | B42: 766.3 | C42: 1072.2 | D42: 878.7 | E42: 1389.1 | F42: 1176.9 | G42: 0 | H42: 0 | I42: 0 | J42: 0 | K42: 0 | L42: 0
A44: NWC | E44: ='Balance Sheet'!E5+'Balance Sheet'!E8+'Balance Sheet'!E11+'Balance Sheet'!E15-'Balance Sheet'!E39-'Balance Sheet'!E42-'Balance Sheet'!E46-'Balance Sheet'!E48-'Balance Sheet'!E49 -> -1184.4 | F44: ='Balance Sheet'!F5+'Balance Sheet'!F8+'Balance Sheet'!F11+'Balance Sheet'!F15-'Balance Sheet'!F39-'Balance Sheet'!F42-'Balance Sheet'!F46-'Balance Sheet'!F48-'Balance Sheet'!F49 -> -1732.6 | G44: ='Balance Sheet'!G5+'Balance Sheet'!G8+'Balance Sheet'!G11+'Balance Sheet'!G15-'Balance Sheet'!G39-'Balance Sheet'!G42-'Balance Sheet'!G46-'Balance Sheet'!G48-'Balance Sheet'!G49 -> -1201.2994 | H44: ='Balance Sheet'!H5+'Balance Sheet'!H8+'Balance Sheet'!H11+'Balance Sheet'!H15-'Balance Sheet'!H39-'Balance Sheet'!H42-'Balance Sheet'!H46-'Balance Sheet'!H48-'Balance Sheet'!H49 -> -971.52282 | I44: ='Balance Sheet'!I5+'Balance Sheet'!I8+'Balance Sheet'!I11+'Balance Sheet'!I15-'Balance Sheet'!I39-'Balance Sheet'!I42-'Balance Sheet'!I46-'Balance Sheet'!I48-'Balance Sheet'!I49 -> -768.11654 | J44: ='Balance Sheet'!J5+'Balance Sheet'!J8+'Balance Sheet'!J11+'Balance Sheet'!J15-'Balance Sheet'!J39-'Balance Sheet'!J42-'Balance Sheet'!J46-'Balance Sheet'!J48-'Balance Sheet'!J49 -> -514.11387 | K44: ='Balance Sheet'!K5+'Balance Sheet'!K8+'Balance Sheet'!K11+'Balance Sheet'!K15-'Balance Sheet'!K39-'Balance Sheet'!K42-'Balance Sheet'!K46-'Balance Sheet'!K48-'Balance Sheet'!K49 -> -308.79017 | L44: ='Balance Sheet'!L5+'Balance Sheet'!L8+'Balance Sheet'!L11+'Balance Sheet'!L15-'Balance Sheet'!L39-'Balance Sheet'!L42-'Balance Sheet'!L46-'Balance Sheet'!L48-'Balance Sheet'!L49 -> -141.59118
A45: Changes in NWC | F45: =F44-E44 -> -548.2 | G45: =G44-F44 -> 531.30063 | H45: =H44-G44 -> 229.77655 | I45: =I44-H44 -> 203.40628 | J45: =J44-I44 -> 254.00267 | K45: =K44-J44 -> 205.3237 | L45: =L44-K44 -> 167.19899

Sheet Revenue Build
B1: 2014A | C1: 2015A | D1: 2016A | E1: 2017A | F1: 2018A | G1: 1Q 2019 | H1: 2Q 2019 | I1: 3Q 2019 | J1: 4Q 2019 | K1: 2019A | L1: 1Q 2020 | M1: 2Q 2020 | N1: 3Q 2020 | O1: 4Q 2020 | P1: 2020E | Q1: 1Q 2021 | R1: 2Q 2021 | S1: 3Q 2021 | T1: 4Q 2021 | U1: 2021E | V1: 1Q 2022 | W1: 2Q 2022 | X1: 3Q 2022 | Y1: 4Q 2022 | Z1: 2022E | AA1: 1Q 2023 | AB1: 2Q 2023 | AC1: 3Q 2023 | AD1: 4Q 2023 | AE1: 2023E | AF1: 1Q 2024 | AG1: 2Q 2024 | AH1: 3Q 2024 | AI1: 4Q 2024 | AJ1: 2024E
A2: Net revenues:
A3: Company-operated stores | B3: 12977.9 | C3: 15197.3 | D3: 16844.1 | E3: 17650.7 | F3: 19690.3 | G3: 5370.3 | H3: 5159 | I3: 5535.5 | J3: =K3-G3-H3-I3 -> 5479.6 | K3: 21544.4 | L3: =L43+L55 -> 5682.3925 | M3: =M43+M55 -> 5552.5499 | N3: =N43+N55 -> 5972.0922 | O3: =O43+O55 -> 6110.1714 | P3: =P43+P55 -> 23837.985 | Q3: =Q43+Q55 -> 6135.1377 | R3: =R43+R55 -> 6050.9778 | S3: =S43+S55 -> 6503.0769 | ... AJ3: =AJ43+AJ55 -> 32897.494
A4: Y/y growth | C4: =C3/B3-1 -> 0.1710138 | D4: =D3/C3-1 -> 0.10836135 | E4: =E3/D3-1 -> 0.047886203 | F4: =F3/E3-1 -> 0.11555349 | K4: =K3/F3-1 -> 0.094163116 | P4: =P3/K3-1 -> 0.10645853 | U4: =U3/P3-1 -> 0.087992511 | Z4: =Z3/U3-1 -> 0.085133504 | AE4: =AE3/Z3-1 -> 0.08189341 | AJ4: =AJ3/AE3-1 -> 0.080437686
A5: Licensed stores | B5: 1588.6 | C5: 1861.9 | D5: 2154.2 | E5: 2355 | F5: 2652.2 | G5: 737.1 | H5: 678.2 | I5: 660.6 | J5: =K5-G5-H5-I5 -> 799.1 | K5: 2875 | L5: =L47+L59 -> 831.55733 | M5: =M47+M59 -> 763.07323 | N5: =N47+N59 -> 740.67783 | O5: =O47+O59 -> 875.29887 | P5: =P47+P59 -> 3284.9718 | Q5: =Q47+Q59 -> 900.17674 | R5: =R47+R59 -> 825.32139 | S5: =S47+S59 -> 800.421 | ... AJ5: =AJ47+AJ59 -> 4388.2136
A6: Y/y growth | C6: =C5/B5-1 -> 0.17203827 | D6: =D5/C5-1 -> 0.15699017 | E6: =E5/D5-1 -> 0.093213258 | F6: =F5/E5-1 -> 0.12619958 | K6: =K5/F5-1 -> 0.084005731 | P6: =P5/K5-1 -> 0.14259888 | U6: =U5/P5-1 -> 0.079693209 | Z6: =Z5/U5-1 -> 0.076397111 | AE6: =AE5/Z5-1 -> 0.073445558 | AJ6: =AJ5/AE5-1 -> 0.070787267
A7: CPG, foodservice and other | B7: 1881.3 | C7: 2103.5 | D7: 2317.6 | E7: 2381.1 | F7: 2377 | G7: 525.3 | H7: 468.7 | I7: 589.3 | J7: =K7-G7-H7-I7 -> 505.9 | K7: 2089.2 | L7: =L61 -> 530.553 | M7: =M61 -> 473.387 | N7: =N61 -> 595.193 | O7: =O61 -> 510.959 | P7: =P61 -> 2110.092 | Q7: =Q61 -> 535.85853 | R7: =R61 -> 478.12087 | S7: =S61 -> 601.14493 | ... AJ7: =AJ61 -> 2195.7702
A8: Y/y growth | C8: =C7/B7-1 -> 0.11810982 | D8: =D7/C7-1 -> 0.10178274 | E8: =E7/D7-1 -> 0.027399033 | F8: =F7/E7-1 -> -0.0017218932 | K8: =K7/F7-1 -> -0.12107699 | P8: =P7/K7-1 -> 0.01 | U8: =U7/P7-1 -> 0.01 | Z8: =Z7/U7-1 -> 0.01 | AE8: =AE7/Z7-1 -> 0.01 | AJ8: =AJ7/AE7-1 -> 0.01
A9: Total net revenues | B9: =B3+B5+B7 -> 16447.8 | C9: =C3+C5+C7 -> 19162.7 | D9: =D3+D5+D7 -> 21315.9 | E9: =E3+E5+E7 -> 22386.8 | F9: =F3+F5+F7 -> 24719.5 | G9: =G3+G5+G7 -> 6632.7 | H9: =H3+H5+H7 -> 6305.9 | I9: =I3+I5+I7 -> 6785.4 | J9: =K9-G9-H9-I9 -> 6784.6 | K9: =K3+K5+K7 -> 26508.6 | L9: =L64 -> 7044.5029 | M9: =M64 -> 6789.0102 | N9: =N64 -> 7307.963 | O9: =O64 -> 7496.4293 | P9: =P64 -> 29233.049 | Q9: =Q64 -> 7571.173 | R9: =R64 -> 7354.4201 | S9: =S64 -> 7904.6428 | ... AJ9: =AJ64 -> 39481.478
A10: Y/y growth | C10: =C9/B9-1 -> 0.16506159 | D10: =D9/C9-1 -> 0.11236412 | E10: =E9/D9-1 -> 0.050239493 | F10: =F9/E9-1 -> 0.1041998 | K10: =K9/F9-1 -> 0.072376059 | P10: =P9/K9-1 -> 0.10277604 | U10: =U9/P9-1 -> 0.081430269 | Z10: =Z9/U9-1 -> 0.079088306 | AE10: =AE9/Z9-1 -> 0.076411679 | AJ10: =AJ9/AE9-1 -> 0.075190414
A12: Net stores opened/closed and transferred:
A13: Americas:
A14: Company operated stores | B14: 317 | C14: 277 | D14: 348 | E14: 395 | F14: 275 | G14: 84 | H14: -1 | I14: 82 | J14: 117 | K14: =SUM(G14:J14) -> 282 | L14: 75 | M14: 75 | N14: 75 | O14: 75 | P14: =L14+M14+O14+N14 -> 300 | Q14: 75 | R14: 75 | S14: 75 | T14: 75 | U14: =Q14+R14+T14+S14 -> 300 | V14: 75 | W14: 75 | X14: 75 | Y14: 75 | Z14: =V14+W14+Y14+X14 -> 300 | AA14: 75 | AB14: 75 | AC14: 75 | AD14: 75 | AE14: =AA14+AB14+AD14+AC14 -> 300 | AF14: 75 | AG14: 75 | AH14: 75 | AI14: 75 | AJ14: =AF14+AG14+AI14+AH14 -> 300
A15: Licensed stores | B15: 381 | C15: 336 | D15: 456 | E15: 558 | F15: 624 | G15: 106 | H15: 67 | I15: 53 | J15: 97 | K15: =SUM(G15:J15) -> 323 | L15: 75 | M15: 75 | N15: 75 | O15: 75 | P15: =L15+M15+O15+N15 -> 300 | Q15: 75 | R15: 75 | S15: 75 | T15: 75 | U15: =Q15+R15+T15+S15 -> 300 | V15: 75 | W15: 75 | X15: 75 | Y15: 75 | Z15: =V15+W15+Y15+X15 -> 300 | AA15: 75 | AB15: 75 | AC15: 75 | AD15: 75 | AE15: =AA15+AB15+AD15+AC15 -> 300 | AF15: 75 | AG15: 75 | AH15: 75 | AI15: 75 | AJ15: =AF15+AG15+AI15+AH15 -> 300
A16: International:
A17: Company operated stores | B17: =250+9 -> 259 | C17: =1320-80 -> 1240 | D17: =359+-214 -> 145 | E17: =259+-21 -> 238 | F17: =2089+-12 -> 2077 | G17: =191+-3 -> 188 | H17: =133+-95 -> 38 | I17: =-217+-16 -> -233 | J17: =200+14 -> 214 | K17: =SUM(G17:J17) -> 207 | L17: 175 | M17: 175 | N17: 175 | O17: 175 | P17: =L17+M17+O17+N17 -> 700 | Q17: 175 | R17: 175 | S17: 175 | T17: 175 | U17: =Q17+R17+T17+S17 -> 700 | V17: 175 | W17: 175 | X17: 175 | Y17: 175 | Z17: =V17+W17+Y17+X17 -> 700 | AA17: 175 | AB17: 175 | AC17: 175 | AD17: 175 | AE17: =AA17+AB17+AD17+AC17 -> 700 | AF17: 175 | AG17: 175 | AH17: 175 | AI17: 175 | AJ17: =AF17+AG17+AI17+AH17 -> 700
A18: Licensed stores | B18: =492+180 -> 672 | C18: =-482+302 -> -180 | D18: =622+494 -> 1116 | E18: =777+353 -> 1130 | F18: =1038+358 -> 1396 | G18: =68+104 -> 172 | H18: =71+142 -> 213 | I18: =470+71 -> 541 | J18: =71+131 -> 202 | K18: =SUM(G18:J18) -> 1128 | L18: 175 | M18: 175 | N18: 175 | O18: 175 | P18: =L18+M18+O18+N18 -> 700 | Q18: 175 | R18: 175 | S18: 175 | T18: 175 | U18: =Q18+R18+T18+S18 -> 700 | V18: 175 | W18: 175 | X18: 175 | Y18: 175 | Z18: =V18+W18+Y18+X18 -> 700 | AA18: 175 | AB18: 175 | AC18: 175 | AD18: 175 | AE18: =AA18+AB18+AD18+AC18 -> 700 | AF18: 175 | AG18: 175 | AH18: 175 | AI18: 175 | AJ18: =AF18+AG18+AI18+AH18 -> 700
A19: All other segments
A20: Company operated stores | B20: 12 | C20: 6 | D20: -17 | E20: -68 | F20: -282 | G20: 3 | H20: 2 | I20: -1 | J20: 0 | K20: =SUM(G20:J20) -> 4 | L20: -12 | M20: 0 | N20: 0 | O20: 0 | P20: 0 | Q20: 0 | R20: 0 | S20: 0 | T20: 0 | U20: 0 | V20: 0 | W20: 0 | X20: 0 | Y20: 0 | Z20: 0 | AA20: 0 | AB20: 0 | AC20: 0 | AD20: 0 | AE20: 0 | AF20: 0 | AG20: 0 | AH20: 0 | AI20: 0 | AJ20: 0
A21: Licensed stores | B21: -24 | C21: -1 | D21: -6 | E21: 2 | F21: -25 | G21: -12 | H21: 0 | I21: 0 | J21: 0 | K21: =SUM(G21:J21) -> -12 | L21: 0 | M21: 0 | N21: 0 | O21: 0 | P21: 0 | Q21: 0 | R21: 0 | S21: 0 | T21: 0 | U21: 0 | V21: 0 | W21: 0 | X21: 0 | Y21: 0 | Z21: 0 | AA21: 0 | AB21: 0 | AC21: 0 | AD21: 0 | AE21: 0 | AF21: 0 | AG21: 0 | AH21: 0 | AI21: 0 | AJ21: 0
A23: Company operated store count change | B23: =B14+B17+B20 -> 588 | C23: =C14+C17+C20 -> 1523 | D23: =D14+D17+D20 -> 476 | E23: =E14+E17+E20 -> 565 | F23: =F14+F17+F20 -> 2070 | G23: =G14+G17+G20 -> 275 | H23: =H14+H17+H20 -> 39 | I23: =I14+I17+I20 -> -152 | ... AJ23: =AJ14+AJ17+AJ20 -> 1000
A24: Licensed store count change | B24: =B15+B18+B21 -> 1029 | C24: =C15+C18+C21 -> 155 | D24: =D15+D18+D21 -> 1566 | E24: =E15+E18+E21 -> 1690 | F24: =F15+F18+F21 -> 1995 | G24: =G15+G18+G21 -> 266 | H24: =H15+H18+H21 -> 280 | I24: =I15+I18+I21 -> 594 | ... AJ24: =AJ15+AJ18+AJ21 -> 1000
A25: Total stores opened/closed and transferred | B25: =B23+B24 -> 1617 | C25: =C23+C24 -> 1678 | D25: =D23+D24 -> 2042 | E25: =E23+E24 -> 2255 | F25: =F23+F24 -> 4065 | G25: =G23+G24 -> 541 | H25: =H23+H24 -> 319 | I25: =I23+I24 -> 442 | ... AJ25: =AJ23+AJ24 -> 2000
A27: Total stores at end of period:
A28: Americas:
A29: Company operated stores | B29: 8395 | C29: =B29+C14 -> 8672 | D29: =C29+D14 -> 9020 | E29: =D29+E14 -> 9415 | F29: =E29+F14 -> 9690 | G29: =F29+G14 -> 9774 | H29: =G29+H14 -> 9773 | I29: =H29+I14 -> 9855 | J29: =I29+J14 -> 9972 | K29: =F29+K14 -> 9972 | L29: =K29+L14 -> 10047 | M29: =L29+M14 -> 10122 | N29: =M29+N14 -> 10197 | O29: =N29+O14 -> 10272 | P29: =O29 -> 10272 | Q29: =P29+Q14 -> 10347 | R29: =Q29+R14 -> 10422 | S29: =R29+S14 -> 10497 | T29: =S29+T14 -> 10572 | U29: =T29 -> 10572 | V29: =U29+V14 -> 10647 | W29: =V29+W14 -> 10722 | X29: =W29+X14 -> 10797 | Y29: =X29+Y14 -> 10872 | Z29: =Y29 -> 10872 | AA29: =Z29+AA14 -> 10947 | AB29: =AA29+AB14 -> 11022 | AC29: =AB29+AC14 -> 11097 | AD29: =AC29+AD14 -> 11172 | AE29: =AD29 -> 11172 | AF29: =AE29+AF14 -> 11247 | AG29: =AF29+AG14 -> 11322 | AH29: =AG29+AH14 -> 11397 | AI29: =AH29+AI14 -> 11472 | AJ29: =AI29 -> 11472
A30: Licensed stores | B30: 5796 | C30: =B30+C15 -> 6132 | D30: =C30+D15 -> 6588 | E30: =D30+E15 -> 7146 | F30: =E30+F15 -> 7770 | G30: =F30+G15 -> 7876 | H30: =G30+H15 -> 7943 | I30: =H30+I15 -> 7996 | J30: =I30+J15 -> 8093 | K30: =F30+K15 -> 8093 | L30: =K30+L15 -> 8168 | M30: =L30+M15 -> 8243 | N30: =M30+N15 -> 8318 | O30: =N30+O15 -> 8393 | P30: =O30 -> 8393 | Q30: =P30+Q15 -> 8468 | R30: =Q30+R15 -> 8543 | S30: =R30+S15 -> 8618 | T30: =S30+T15 -> 8693 | U30: =T30 -> 8693 | V30: =U30+V15 -> 8768 | W30: =V30+W15 -> 8843 | X30: =W30+X15 -> 8918 | Y30: =X30+Y15 -> 8993 | Z30: =Y30 -> 8993 | AA30: =Z30+AA15 -> 9068 | AB30: =AA30+AB15 -> 9143 | AC30: =AB30+AC15 -> 9218 | AD30: =AC30+AD15 -> 9293 | AE30: =AD30 -> 9293 | AF30: =AE30+AF15 -> 9368 | AG30: =AF30+AG15 -> 9443 | AH30: =AG30+AH15 -> 9518 | AI30: =AH30+AI15 -> 9593 | AJ30: =AI30 -> 9593
A31: International:
A32: Company operated stores | B32: 2980 | C32: =B32+C17 -> 4220 | D32: =C32+D17 -> 4365 | E32: =D32+E17 -> 4603 | F32: =E32+F17 -> 6680 | G32: =F32+G17 -> 6868 | H32: =G32+H17 -> 6906 | I32: =H32+I17 -> 6673 | J32: =I32+J17 -> 6887 | K32: =F32+K17 -> 6887 | L32: =K32+L17 -> 7062 | M32: =L32+M17 -> 7237 | N32: =M32+N17 -> 7412 | O32: =N32+O17 -> 7587 | P32: =O32 -> 7587 | Q32: =P32+Q17 -> 7762 | R32: =Q32+R17 -> 7937 | S32: =R32+S17 -> 8112 | T32: =S32+T17 -> 8287 | U32: =T32 -> 8287 | V32: =U32+V17 -> 8462 | W32: =V32+W17 -> 8637 | X32: =W32+X17 -> 8812 | Y32: =X32+Y17 -> 8987 | Z32: =Y32 -> 8987 | AA32: =Z32+AA17 -> 9162 | AB32: =AA32+AB17 -> 9337 | AC32: =AB32+AC17 -> 9512 | AD32: =AC32+AD17 -> 9687 | AE32: =AD32 -> 9687 | AF32: =AE32+AF17 -> 9862 | AG32: =AF32+AG17 -> 10037 | AH32: =AG32+AH17 -> 10212 | AI32: =AH32+AI17 -> 10387 | AJ32: =AI32 -> 10387
A33: Licensed stores | B33: 3507 | C33: =B33+C18 -> 3327 | D33: =C33+D18 -> 4443 | E33: =D33+E18 -> 5573 | F33: =E33+F18 -> 6969 | G33: =F33+G18 -> 7141 | H33: =G33+H18 -> 7354 | I33: =H33+I18 -> 7895 | J33: =I33+J18 -> 8097 | K33: =F33+K18 -> 8097 | L33: =K33+L18 -> 8272 | M33: =L33+M18 -> 8447 | N33: =M33+N18 -> 8622 | O33: =N33+O18 -> 8797 | P33: =O33 -> 8797 | Q33: =P33+Q18 -> 8972 | R33: =Q33+R18 -> 9147 | S33: =R33+S18 -> 9322 | T33: =S33+T18 -> 9497 | U33: =T33 -> 9497 | V33: =U33+V18 -> 9672 | W33: =V33+W18 -> 9847 | X33: =W33+X18 -> 10022 | Y33: =X33+Y18 -> 10197 | Z33: =Y33 -> 10197 | AA33: =Z33+AA18 -> 10372 | AB33: =AA33+AB18 -> 10547 | AC33: =AB33+AC18 -> 10722 | AD33: =AC33+AD18 -> 10897 | AE33: =AD33 -> 10897 | AF33: =AE33+AF18 -> 11072 | AG33: =AF33+AG18 -> 11247 | AH33: =AG33+AH18 -> 11422 | AI33: =AH33+AI18 -> 11597 | AJ33: =AI33 -> 11597
A34: All other segments
A35: Company operated stores | B35: 369 | C35: =B35+C20 -> 375 | D35: =C35+D20 -> 358 | E35: =D35+E20 -> 290 | F35: =E35+F20 -> 8 | G35: =F35+G20 -> 11 | H35: =G35+H20 -> 13 | I35: =H35+I20 -> 12 | J35: =I35+J20 -> 12 | K35: =F35+K20 -> 12 | L35: =K35+L20 -> 0 | M35: =L35+M20 -> 0 | N35: =M35+N20 -> 0 | O35: =N35+O20 -> 0 | P35: =O35 -> 0 | Q35: =P35+Q20 -> 0 | R35: =Q35+R20 -> 0 | S35: =R35+S20 -> 0 | T35: =S35+T20 -> 0 | U35: =T35 -> 0 | V35: =U35+V20 -> 0 | W35: =V35+W20 -> 0 | X35: =W35+X20 -> 0 | Y35: =X35+Y20 -> 0 | Z35: =Y35 -> 0 | AA35: =Z35+AA20 -> 0 | AB35: =AA35+AB20 -> 0 | AC35: =AB35+AC20 -> 0 | AD35: =AC35+AD20 -> 0 | AE35: =AD35 -> 0 | AF35: =AE35+AF20 -> 0 | AG35: =AF35+AG20 -> 0 | AH35: =AG35+AH20 -> 0 | AI35: =AH35+AI20 -> 0 | AJ35: =AI35 -> 0
A36: Licensed stores | B36: 42 | C36: =B36+C21 -> 41 | D36: =C36+D21 -> 35 | E36: =D36+E21 -> 37 | F36: =E36+F21 -> 12 | G36: =F36+G21 -> 0 | H36: =G36+H21 -> 0 | I36: =H36+I21 -> 0 | J36: =I36+J21 -> 0 | K36: =F36+K21 -> 0 | L36: =K36+L21 -> 0 | M36: =L36+M21 -> 0 | N36: =M36+N21 -> 0 | O36: =N36+O21 -> 0 | P36: =O36 -> 0 | Q36: =P36+Q21 -> 0 | R36: =Q36+R21 -> 0 | S36: =R36+S21 -> 0 | T36: =S36+T21 -> 0 | U36: =T36 -> 0 | V36: =U36+V21 -> 0 | W36: =V36+W21 -> 0 | X36: =W36+X21 -> 0 | Y36: =X36+Y21 -> 0 | Z36: =Y36 -> 0 | AA36: =Z36+AA21 -> 0 | AB36: =AA36+AB21 -> 0 | AC36: =AB36+AC21 -> 0 | AD36: =AC36+AD21 -> 0 | AE36: =AD36 -> 0 | AF36: =AE36+AF21 -> 0 | AG36: =AF36+AG21 -> 0 | AH36: =AG36+AH21 -> 0 | AI36: =AH36+AI21 -> 0 | AJ36: =AI36 -> 0
A37: Total company operated stores | B37: =B29+B32+B35 -> 11744 | C37: =C29+C32+C35 -> 13267 | D37: =D29+D32+D35 -> 13743 | E37: =E29+E32+E35 -> 14308 | F37: =F29+F32+F35 -> 16378 | G37: =G29+G32+G35 -> 16653 | H37: =H29+H32+H35 -> 16692 | I37: =I29+I32+I35 -> 16540 | ... AJ37: =AJ29+AJ32+AJ35 -> 21859
A38: Total licensed stores | B38: =B30+B33+B36 -> 9345 | C38: =C30+C33+C36 -> 9500 | D38: =D30+D33+D36 -> 11066 | E38: =E30+E33+E36 -> 12756 | F38: =F30+F33+F36 -> 14751 | G38: =G30+G33+G36 -> 15017 | H38: =H30+H33+H36 -> 15297 | I38: =I30+I33+I36 -> 15891 | ... AJ38: =AJ30+AJ33+AJ36 -> 21190
A39: Total stores | B39: =B37+B38 -> 21089 | C39: =C37+C38 -> 22767 | D39: =D37+D38 -> 24809 | E39: =E37+E38 -> 27064 | F39: =F37+F38 -> 31129 | G39: =G37+G38 -> 31670 | H39: =H37+H38 -> 31989 | I39: =I37+I38 -> 32431 | ... AJ39: =AJ37+AJ38 -> 43049
A41: Same store sales:
A42: Company operated stores:
A43: Total sales | B43: =B3 -> 12977.9 | C43: =C3 -> 15197.3 | D43: =D3 -> 16844.1 | E43: =E3 -> 17650.7 | F43: =F3 -> 19690.3 | G43: =G3 -> 5370.3 | H43: =H3 -> 5159 | I43: =I3 -> 5535.5 | ... K43: =K3 -> 21544.4 | L43: =L44*(L37-L23) -> 5642.5924 | M43: =M44*(M37-M23) -> 5512.2767 | N43: =N44*(N37-N23) -> 5929.3953 | O43: =O44*(O37-O23) -> 6067.1032 | P43: =SUM(L43:O43) -> 23151.368 | Q43: =Q44*(Q37-Q23) -> 6092.4947 | R43: =R44*(R37-R23) -> 6009.4964 | S43: =S44*(S37-S23) -> 6459.0991 | T43: =T44*(T37-T23) -> 6668.1148 | U43: =SUM(Q43:T43) -> 25229.205 | V43: =V44*(V37-V23) -> 6562.3117 | W43: =W44*(W37-W23) -> 6531.5882 | X43: =X44*(X37-X23) -> 7015.2487 | Y43: =Y44*(Y37-Y23) -> 7307.4999 | Z43: =SUM(V43:Y43) -> 27416.648 | AA43: =AA44*(AA37-AA23) -> 7048.4844 | AB43: =AB44*(AB37-AB23) -> 7079.5969 | AC43: =AC44*(AC37-AC23) -> 7598.9541 | AD43: =AD44*(AD37-AD23) -> 7987.3668 | AE43: =SUM(AA43:AD43) -> 29714.402 | AF43: =AF44*(AF37-AF23) -> 7551.4791 | AG43: =AG44*(AG37-AG23) -> 7654.6078 | AH43: =AH44*(AH37-AH23) -> 8211.368 | AI43: =AI44*(AI37-AI23) -> 8709.9311 | AJ43: =SUM(AF43:AI43) -> 32127.386
A44: Comparable sales per store | B44: =B43/(B37-B23) -> 1.1633112 | C44: =C43/(C37-C23) -> 1.294048 | D44: =D43/(D37-D23) -> 1.2696239 | E44: =E43/(E37-E23) -> 1.2843411 | F44: =F43/(F37-F23) -> 1.3761742 | G44: =G43/(G37-G23) -> 0.32789718 | H44: =H43/(H37-H23) -> 0.30979403 | I44: =I43/(I37-I23) -> 0.33162593 | ... K44: =K43/(K37-K23) -> 1.3154476 | L44: =(L45+1)*G44 -> 0.33445512 | M44: =(M45+1)*H44 -> 0.32218579 | N44: =(N45+1)*I44 -> 0.34157471 | O44: =(O45+1)*J44 -> 0.34454559 | P44: =P43/(P37-P23) -> 1.3732349 | Q44: =(Q45+1)*L44 -> 0.34114423 | R44: =(R45+1)*M44 -> 0.33185137 | S44: =(S45+1)*N44 -> 0.35182195 | T44: =(T45+1)*O44 -> 0.35832741 | U44: =U43/(U37-U23) -> 1.4126886 | V44: =(V45+1)*Q44 -> 0.34796711 | W44: =(W45+1)*R44 -> 0.34180691 | X44: =(X45+1)*S44 -> 0.36237661 | Y44: =(Y45+1)*T44 -> 0.37266051 | Z44: =Z43/(Z37-Z23) -> 1.45377 | AA44: =(AA45+1)*V44 -> 0.35492645 | AB44: =(AB45+1)*W44 -> 0.35206111 | AC44: =(AC45+1)*X44 -> 0.3732479 | AD44: =(AD45+1)*Y44 -> 0.38756693 | AE44: =SUM(AA44:AD44) -> 1.4678024 | AF44: =(AF45+1)*AA44 -> 0.36202498 | AG44: =(AG45+1)*AB44 -> 0.36262295 | AH44: =(AH45+1)*AC44 -> 0.38444534 | AI44: =(AI45+1)*AD44 -> 0.4030696 | AJ44: =AJ43/(AJ37-AJ23) -> 1.540217
...

Sheet DCF
C1: 0.25 | D1: 1.25 | E1: 2.25 | F1: 3.25 | G1: 4.25 | H1: 5.25
B2: USD: millions | C2: 2019E | D2: 2020E | E2: 2021E | F2: 2022E | G2: 2023E | H2: 2024E | J2: WACC
B3: EBITDA | C3: ='Income Statement'!S48 -> 5759.6268 | D3: ='Income Statement'!T48 -> 6638.3387 | E3: ='Income Statement'!U48 -> 7291.0866 | F3: ='Income Statement'!V48 -> 7960.4027 | G3: ='Income Statement'!W48 -> 8633.998 | H3: ='Income Statement'!X48 -> 9337.1713 | J3: % Equity | K3: ='Balance Sheet'!F64/('Balance Sheet'!F39+'Balance Sheet'!F64) -> 0.49791383
B4: Operating Income (EBIT) | C4: ='Income Statement'!S30 -> 4400.1121 | D4: ='Income Statement'!T30 -> 5089.3938 | E4: ='Income Statement'!U30 -> 5537.2863 | F4: ='Income Statement'!V30 -> 5985.5451 | G4: ='Income Statement'!W30 -> 6421.1919 | H4: ='Income Statement'!X30 -> 6868.5253 | J4: Re | K4: =K15 -> 0.10799111
B5: (+) D&A | C5: ='Cash Flows'!G5 -> 1359.5147 | D5: ='Cash Flows'!H5 -> 1548.9449 | E5: ='Cash Flows'!I5 -> 1753.8004 | F5: ='Cash Flows'!J5 -> 1974.8576 | G5: ='Cash Flows'!K5 -> 2212.8061 | H5: ='Cash Flows'!L5 -> 2468.6461 | J5: % Debt | K5: =1-K3 -> 0.50208617
B6: (-) Taxes | C6: ='Income Statement'!S42 -> 999.13341 | D6: ='Income Statement'!T42 -> 1011.1144 | E6: ='Income Statement'!U42 -> 1093.9362 | F6: ='Income Statement'!V42 -> 1175.8179 | G6: ='Income Statement'!W42 -> 1254.0116 | H6: ='Income Statement'!X42 -> 1333.2022 | J6: Rd | K6: 0.0418
B7: (-) Changes in NWC | C7: ='Cash Flows'!G45 -> 531.30063 | D7: ='Cash Flows'!H45 -> 229.77655 | E7: ='Cash Flows'!I45 -> 203.40628 | F7: ='Cash Flows'!J45 -> 254.00267 | G7: ='Cash Flows'!K45 -> 205.3237 | H7: ='Cash Flows'!L45 -> 167.19899 | J7: Tax Rate | K7: ='Income Statement'!R43 -> 0.2183391
B8: (-) Capex | C8: ='Cash Flows'!G26 -> -1908.6192 | D8: ='Cash Flows'!H26 -> -2104.7795 | E8: ='Cash Flows'!I26 -> -2276.1723 | F8: ='Cash Flows'!J26 -> -2456.1909 | G8: ='Cash Flows'!K26 -> -2643.8726 | H8: ='Cash Flows'!L26 -> -2842.6664 | J8: WACC | K8: =K3*K4+K5*K6*(1-K7) -> 0.07017514
B9: Unlevered FCF | C9: =C4+C5-C6-C7-C8 -> 6137.812 | D9: =D4+D5-D6-D7-D8 -> 7502.2272 | E9: =E4+E5-E6-E7-E8 -> 8269.9164 | F9: =F4+F5-F6-F7-F8 -> 8986.773 | G9: =G4+G5-G6-G7-G8 -> 9818.5353 | H9: =H4+H5-H6-H7-H8 -> 10679.437
B10: NPV | C10: =C9/4*(1+K8)^C1 -> 1560.6924 | D10: =D9/4*(1+K8)^D1 -> 2041.4972 | E10: =E9/4*(1+K8)^E1 -> 2408.322 | F10: =F9/4*(1+K8)^F1 -> 2800.7353 | G10: =G9/4*(1+K8)^G1 -> 3274.6875 | H10: =H9/4*(1+K8)^H1 -> 3811.7671
J11: CAPM
B12: NPV of Projection Period | C12: =SUM(C10:H10) -> 15897.702 | J12: Beta | K12: =0.8*(1+(1-K7)*'Balance Sheet'!F51/'Balance Sheet'!F4) -> 1.4491741
J13: MRP | K13: 0.0592
C14: Perpetuity Growth | F14: Multiple | J14: Rf Rate | K14: 0.0222
C15: 2025 | D15: =H9*(1+D16) -> 10786.231 | F15: EV/EBITDA | G15: 18 | J15: Re | K15: =K12*K13+K14 -> 0.10799111
C16: Growth rate | D16: 0.01 | F16: TV in 2024 | G16: =H3*G15 -> 168069.08
C17: Discount factor | D17: =K8-D16 -> 0.06017514 | F17: NPV of TV | G17: =G16/(1+K8)^H1 -> 117719.88
C18: TV in 2024 | D18: =D15/D17 -> 179247.29 | F18: Enterprise Value | G18: =G17+C12 -> 133617.59
C19: NPV of TV | D19: =D18/(1+K8)^H1 -> 125549.39 | F19: (-Debt) | G19: ='Balance Sheet'!F51 -> 9090.2
C20: Enterprise Value | D20: =D19+C12 -> 141447.09 | F20: (+Cash) | G20: ='Balance Sheet'!F4 -> 8756.3
C21: (-Debt) | D21: ='Balance Sheet'!F51 -> 9090.2 | F21: Equity Value | G21: =G18-G19+G20 -> 133283.69
C22: (+Cash) | D22: ='Balance Sheet'!F4 -> 8756.3 | F22: Diluted shares outstanding | G22: 1233.2
C23: Equity Value | D23: =D20-D21+D22 -> 141113.19 | F23: Target Price | G23: =G21/G22 -> 108.07954
C24: Diluted shares outstanding | D24: 1233.2 | F24: Current Share Price | G24: 85.4
C25: Target Price | D25: =D23/D24 -> 114.42847 | F25: Implied Upside | G25: =(G23-G24)/G24 -> 0.26556836
C26: Current Share Price | D26: 85.4
C27: Implied Upside | D27: =(D25-D26)/D26 -> 0.33991182
C29: Sensitivity Analysis
E30: Perpetuity Growth Rate
